Workbook

Sheet 1.Necessidades do cliente
A1: Etapa do Ciclo de Vida | B1: Tipo de Cliente | C1: Necessidades do Cliente
A2: Planejamento do Produto | B2: Cliente Interno/Cliente Externo | C2: Possuir um custo benefício bom para que o produto seja viável; Ser mais barato que a perda por danificação da ferramenta.
A3: Desenvolvimento do Produto | B3: Cliente Interno/Cliente Intermediário/Cliente Externo | C3: Ocupar pouco espaço; Ter boa durabilidade; Assegurar a movimentação das ferramentas na obra; Fácil armazenagem; Fácil substituição de peças danificadas;
A4: Preparação para Produção | B4: Cliente Interno | C4: Molde para usar como base de produção; Ter matéria prima acessível
A5: Produção | B5: Cliente Interno | C5: Produção ágil; Capacidade de ser produzido de forma modular
A6: Estoque / Armazenagem | B6: Cliente Intermediário/Cliente Externo | C6: Material que aguenta intempéries de estocagem
A7: Venda do Produto | B7: Cliente Intermediário | C7: O produto ser chamativo; Aparência robusta
A8: Montagem do Produto | B8: Cliente Interno | C8: Ter montagem rápida.
A9: Embalagem | B9: Cliente Interno | C9: Embalagem simples.
A10: Distribuição e Logística | B10: Cliente Intermediário | C10: O produto não danificar; Ter fornecimento constante
A11: Uso e Suporte | B11: Cliente Externo | C11: Facilidade de reparo; Facilidade de movimentação; Ter as ferramentas organizadas;
A12: Função | B12: Cliente Externo | C12: Ter capacidade para suportar as principais ferramentas;
... A14: Fim de Vida e Descarte: | B14: Cliente | C14: Facilidade de desmontagem; Materiais recicláveis para o descarte.

Sheet Página17
A1: Função Principal | B1: Modo de Falha Potencial | C1: Efeito da Falha | D1: Causa(s) | E1: Severidade (S) | F1: Ocorrência (O) | G1: Detecção (D) | H1: RPN (S×O×D) | I1: Ação Recomendável | J1: Controle do Processo
A2: Bloquear Acesso | B2: Trava do módulo não fecha corretamente | C2: Ferramentas podem cair ou serem acessadas indevidamente | D2: Defeito no mecanismo de travamento | E2: 9 | F2: 4 | G2: 3 | H2: 108 | I2: Revisar o mecanismo de travamento e realizar testes de resistência a impactos | J2: Inspeção visual e testes periódicos nas travas
A3: Organizar Ferramentas | B3: Gavetas não se encaixam corretamente | C3: Dificuldade de acesso e perda de organização | D3: Falha no sistema de encaixe ou desgaste dos componentes | E3: 7 | F3: 3 | G3: 4 | H3: 84 | I3: Melhorar tolerância de encaixe das gavetas e realizar manutenção periódica | J3: Testes de encaixe e verificação de desgaste
A4: Movimentar Módulos | B4: Haste retrátil quebra ou falha em travar | C4: Impossibilidade de movimentação do carrinho ou risco de acidentes | D4: Material frágil ou defeito de fabricação | E4: 8 | F4: 3 | G4: 2 | H4: 48 | I4: Usar material mais resistente na haste e testar travas com maior resistência | J4: Testes de carga e resistência periódicos
A5: Movimentar Ferramentas | B5: Ferramentas se soltam ou desorganizam dentro da gaveta | C5: Ferramentas caem ou ficam desorganizadas durante o transporte | D5: Falha no sistema de organização interna das gavetas | E5: 7 | F5: 2 | G5: 5 | H5: 70 | I5: Ajustar sistema de fixação das ferramentas nas gavetas e realizar testes de transporte | J5: Testes de movimentação com carga completa
A6: Bloquear Movimentação | B6: Rodas não travam corretamente | C6: O carrinho pode se mover involuntariamente durante o uso | D6: Defeito nas travas das rodas | E6: 9 | F6: 3 | G6: 3 | H6: 81 | I6: Melhorar o design das travas das rodas e realizar testes em condições de uso real | J6: Inspeção periódica e testes de funcionalidade das rodas

Sheet 2.Matriz de atributos
B1: Estética | C1: Ergonomia | D1: Eficiência | E1: Durabilidade | F1: Econômico | G1: Confiabilidade | H1: Funcionamento
A2: Planejamento do Produto | D2: Ser mais barato que a perda por danificação da ferramenta. | F2: Possuir um custo benefício bom para que o produto seja viável;
A3: Desenvolvimento do Produto | D3: Ocupar pouco espaço; | E3: Ter boa durabilidade | H3: Assegurar a movimentação das ferramentas na obra; Ter fácil armazenagem; Ter fácil substituição de peças danificadas.
A4: Preparação para Produção | D4: Molde para usar como base de produção; | F4: Ter matéria prima acessível
A5: Produção | D5: - Produção ágil | H5: - Capacidade de ser produzido de forma modular
A6: Estoque / Armazenagem | D6: Categorização das peças no estoque | E6: Material que aguenta intempéries de estocagem
A7: Venda do Produto | B7: Aparência robusta e chamativa
A8: Montagem do Produto | D8: - Ter montagem rápida.
A9: Embalagem | D9: -Embalagem simples.
A10: Distribuição e Logística | D10: -Ter fornecimento constante | E10: -O produto não danificar; | G10: -O produto não danificar;
A11: Uso | C11: Ter fácil movimentação | E11: Resistência a desgaste causado pela obra
A12: Função | H12: Ter capacidade para suportar as principais ferramentas.
A13: Manutenção | D13: Ter facilidade na troca de peças | F13: Ter peças de manutenção baratas a pronta entrega | H13: Ter peças de manutenção baratas a pronta entrega
A14: Fim de Vida e Descarte | D14: Facilidade de desmontagem; | H14: Materiais recicláveis para o descarte.

Sheet 3.Lista de Requisitos
A1: ID | B1: Requisitos dos Clientes
A2: 1 | B2: Ter bom custo benefício | E2: Ter custo inferior à média de perda ou danificação das ferramentas.
A3: 2 | B3: Ser de fácil movimentação
A4: 3 | B4: Ser durável
A5: 4 | B5: Ter manutenção simples | E5: Ser compacto para transporte, movimentação e armazenamento fácil.
A6: 5 | B6: Ter compartimentos
A7: 6 | B7: Ter matérias-primas acessíveis | E7: Ter capacidade de suportar as ferramentas especificadas sem deformação ou falha.
A8: 7 | B8: Ter montagem em poucas etapas | E8: Ser durável, com vida útil compatível às condições de obra.
A9: 8 | B9: Ter montagem rápida | E9: Ter manutenção simples, permitindo troca rápida de peças sem ferramentas especiais.
A10: 9 | B10: Ter aparência robusta
A11: 10 | B11: Ter embalagem simples | E11: Ser produzido de forma modular, permitindo montagem, manutenção e produção simplificada.
A12: 11 | B12: Ter fácil desmontagem | E12: Ter utilização de matérias-primas acessíveis e disponíveis no mercado local.
A13: 12 | B13: Ter capacidade para suportar as principais ferramentas
A14: 13 | B14: Ser compacto | E14: Ter montagem rápida, intuitiva e com poucas etapas.
A15: 14 | B15: Ter molde para a produção
E16: Ter design que permita categorização eficiente das peças no estoque.

Sheet 4.Kano
A1: ID | B1: Requisitos dos Clientes | C1: Nível
A2: {=UNIQUE('3.Lista de Requisitos'!$A$2:$A16)} -> 1 | B2: =VLOOKUP(A2,'3.Lista de Requisitos'!$A:$B,2) -> Ter bom custo benefício | C2: Desempenho/unidimensional
A3: 2 | B3: =VLOOKUP(A3,'3.Lista de Requisitos'!$A:$B,2) -> Ser de fácil movimentação | C3: Básico/Must-have
A4: 3 | B4: =VLOOKUP(A4,'3.Lista de Requisitos'!$A:$B,2) -> Ser durável | C4: Básico/Must-have
A5: 4 | B5: =VLOOKUP(A5,'3.Lista de Requisitos'!$A:$B,2) -> Ter manutenção simples | C5: Atrativo
A6: 5 | B6: =VLOOKUP(A6,'3.Lista de Requisitos'!$A:$B,2) -> Ter compartimentos | C6: Básico/Must-have
A7: 6 | B7: =VLOOKUP(A7,'3.Lista de Requisitos'!$A:$B,2) -> Ter matérias-primas acessíveis | C7: Básico/Must-have
A8: 7 | B8: =VLOOKUP(A8,'3.Lista de Requisitos'!$A:$B,2) -> Ter montagem em poucas etapas | C8: Desempenho/unidimensional
A9: 8 | B9: =VLOOKUP(A9,'3.Lista de Requisitos'!$A:$B,2) -> Ter montagem rápida | C9: Desempenho/unidimensional
A10: 9 | B10: =VLOOKUP(A10,'3.Lista de Requisitos'!$A:$B,2) -> Ter aparência robusta | C10: Atrativo
A11: 10 | B11: =VLOOKUP(A11,'3.Lista de Requisitos'!$A:$B,2) -> Ter embalagem simples | C11: Básico/Must-have
A12: 11 | B12: =VLOOKUP(A12,'3.Lista de Requisitos'!$A:$B,2) -> Ter fácil desmontagem | C12: Atrativo
A13: 12 | B13: =VLOOKUP(A13,'3.Lista de Requisitos'!$A:$B,2) -> Ter capacidade para suportar as principais ferramentas | C13: Básico/Must-have
A14: 13 | B14: =VLOOKUP(A14,'3.Lista de Requisitos'!$A:$B,2) -> Ser compacto | C14: Desempenho/unidimensional
A15: 14 | B15: =VLOOKUP(A15,'3.Lista de Requisitos'!$A:$B,2) -> Ter molde para a produção | C15: Básico/Must-have

Sheet 5.Mudge
A1: Requisitos | B1: (0, 1, 3, 5) | C1: B | D1: C | E1: D | F1: E | G1: F | H1: G | I1: H | J1: I | K1: J | L1: K | M1: L | N1: M | O1: N | P1: O | Q1: P | R1: Q | S1: R | T1: S | U1: T | V1: U | W1: W | X1: X | Y1: Y | Z1: Z | AA1: 1A | AB1: 2A | AC1: 3A | AD1: 4A | AE1: TOTAL | AF1: % | AG1: Merge | AH1: Name | AI1: % | AK1: VALORES | BN1: PARÂMETRO
A2: {=UNIQUE('4.Kano'!$B$2:$B1000)} -> Ter bom custo benefício | B2: A | C2: B3 | D2: C1 | E2: A1 | F2: E3 | G2: A1 | H2: G1 | I2: H1 | J2: A1 | K2: A5 | L2: A1 | M2: L3 | N2: M1 | O2: A3 | AE2: =SUMIFS($AK$2:$BL$30,$BN$2:$CO$30,$B2) -> 12 | AF2: =AE2/SUM($AE$2:$AE1000) -> 0.056872038 | AG2: =B2&AE2 -> A12 | AH2: {=UNIQUE($A$2:$A1000)} -> Ter bom custo benefício | AI2: =AF2 -> 0.056872038 | AJ2: =AE2 -> 12 | AK2: =VALUE(RIGHT(C2)) -> 3 | AL2: =VALUE(RIGHT(D2)) -> 1 | AM2: =VALUE(RIGHT(E2)) -> 1 | AN2: =VALUE(RIGHT(F2)) -> 3 | AO2: =VALUE(RIGHT(G2)) -> 1 | AP2: =VALUE(RIGHT(H2)) -> 1 | AQ2: =VALUE(RIGHT(I2)) -> 1 | AR2: =VALUE(RIGHT(J2)) -> 1 | ... BL2: =VALUE(RIGHT(AD2)) -> 0 | BN2: =LEFT(C2) -> B | BO2: =LEFT(D2) -> C | BP2: =LEFT(E2) -> A | BQ2: =LEFT(F2) -> E | BR2: =LEFT(G2) -> A | BS2: =LEFT(H2) -> G | BT2: =LEFT(I2) -> H | BU2: =LEFT(J2) -> A | ... CO2: =LEFT(AD2)
A3: Ser de fácil movimentação | B3: B | D3: B1 | E3: B3 | F3: E1 | G3: B3 | H3: B3 | I3: B3 | J3: B3 | K3: B5 | L3: B1 | M3: L1 | N3: B3 | O3: B3 | AE3: =SUMIFS($AK$2:$BL$30,$BN$2:$CO$30,$B3) -> 31 | AF3: =AE3/SUM($AE$2:$AE1001) -> 0.14691943 | AG3: =B3&AE3 -> B31 | AH3: Ser de fácil movimentação | AI3: =AF3 -> 0.14691943 | AJ3: =AE3 -> 31 | AK3: =VALUE(RIGHT(C3)) -> 0 | AL3: =VALUE(RIGHT(D3)) -> 1 | AM3: =VALUE(RIGHT(E3)) -> 3 | AN3: =VALUE(RIGHT(F3)) -> 1 | AO3: =VALUE(RIGHT(G3)) -> 3 | AP3: =VALUE(RIGHT(H3)) -> 3 | AQ3: =VALUE(RIGHT(I3)) -> 3 | AR3: =VALUE(RIGHT(J3)) -> 3 | ... BL3: =VALUE(RIGHT(AD3)) -> 0 | BN3: =LEFT(C3) | BO3: =LEFT(D3) -> B | BP3: =LEFT(E3) -> B | BQ3: =LEFT(F3) -> E | BR3: =LEFT(G3) -> B | BS3: =LEFT(H3) -> B | BT3: =LEFT(I3) -> B | BU3: =LEFT(J3) -> B | ... CO3: =LEFT(AD3)
A4: Ser durável | B4: C | E4: C1 | F4: E3 | G4: C5 | H4: C3 | I4: C1 | J4: C3 | K4: C5 | L4: C1 | M4: L3 | N4: C1 | O4: C3 | AE4: =SUMIFS($AK$2:$BL$30,$BN$2:$CO$30,$B4) -> 24 | AF4: =AE4/SUM($AE$2:$AE1002) -> 0.11374408 | AG4: =B4&AE4 -> C24 | AH4: Ser durável | AI4: =AF4 -> 0.11374408 | AJ4: =AE4 -> 24 | AK4: =VALUE(RIGHT(C4)) -> 0 | AL4: =VALUE(RIGHT(D4)) -> 0 | AM4: =VALUE(RIGHT(E4)) -> 1 | AN4: =VALUE(RIGHT(F4)) -> 3 | AO4: =VALUE(RIGHT(G4)) -> 5 | AP4: =VALUE(RIGHT(H4)) -> 3 | AQ4: =VALUE(RIGHT(I4)) -> 1 | AR4: =VALUE(RIGHT(J4)) -> 3 | ... BL4: =VALUE(RIGHT(AD4)) -> 0 | BN4: =LEFT(C4) | BO4: =LEFT(D4) | BP4: =LEFT(E4) -> C | BQ4: =LEFT(F4) -> E | BR4: =LEFT(G4) -> C | BS4: =LEFT(H4) -> C | BT4: =LEFT(I4) -> C | BU4: =LEFT(J4) -> C | ... CO4: =LEFT(AD4)
A5: Ter manutenção simples | B5: D | F5: E1 | G5: D3 | H5: D1 | I5: D1 | J5: D1 | K5: D3 | L5: D1 | M5: L3 | N5: M3 | O5: D3 | AE5: =SUMIFS($AK$2:$BL$30,$BN$2:$CO$30,$B5) -> 13 | AF5: =AE5/SUM($AE$2:$AE1003) -> 0.061611374 | AG5: =B5&AE5 -> D13 | AH5: Ter manutenção simples | AI5: =AF5 -> 0.061611374 | AJ5: =AE5 -> 13 | AK5: =VALUE(RIGHT(C5)) -> 0 | AL5: =VALUE(RIGHT(D5)) -> 0 | AM5: =VALUE(RIGHT(E5)) -> 0 | AN5: =VALUE(RIGHT(F5)) -> 1 | AO5: =VALUE(RIGHT(G5)) -> 3 | AP5: =VALUE(RIGHT(H5)) -> 1 | AQ5: =VALUE(RIGHT(I5)) -> 1 | AR5: =VALUE(RIGHT(J5)) -> 1 | ... BL5: =VALUE(RIGHT(AD5)) -> 0 | BN5: =LEFT(C5) | BO5: =LEFT(D5) | BP5: =LEFT(E5) | BQ5: =LEFT(F5) -> E | BR5: =LEFT(G5) -> D | BS5: =LEFT(H5) -> D | BT5: =LEFT(I5) -> D | BU5: =LEFT(J5) -> D | ... CO5: =LEFT(AD5)
A6: Ter compartimentos | B6: E | G6: E3 | H6: E3 | I6: E5 | J6: E3 | K6: E5 | L6: E1 | M6: L1 | N6: E1 | O6: E3 | AE6: =SUMIFS($AK$2:$BL$30,$BN$2:$CO$30,$B6) -> 32 | AF6: =AE6/SUM($AE$2:$AE1004) -> 0.15165877 | AG6: =B6&AE6 -> E32 | AH6: Ter compartimentos | AI6: =AF6 -> 0.15165877 | AJ6: =AE6 -> 32 | AK6: =VALUE(RIGHT(C6)) -> 0 | AL6: =VALUE(RIGHT(D6)) -> 0 | AM6: =VALUE(RIGHT(E6)) -> 0 | AN6: =VALUE(RIGHT(F6)) -> 0 | AO6: =VALUE(RIGHT(G6)) -> 3 | AP6: =VALUE(RIGHT(H6)) -> 3 | AQ6: =VALUE(RIGHT(I6)) -> 5 | AR6: =VALUE(RIGHT(J6)) -> 3 | ... BL6: =VALUE(RIGHT(AD6)) -> 0 | BN6: =LEFT(C6) | BO6: =LEFT(D6) | BP6: =LEFT(E6) | BQ6: =LEFT(F6) | BR6: =LEFT(G6) -> E | BS6: =LEFT(H6) -> E | BT6: =LEFT(I6) -> E | BU6: =LEFT(J6) -> E | ... CO6: =LEFT(AD6)
A7: Ter matérias-primas acessíveis | B7: F | H7: G1 | I7: F1 | J7: I1 | K7: F3 | L7: K3 | M7: L5 | N7: M3 | O7: F1 | AE7: =SUMIFS($AK$2:$BL$30,$BN$2:$CO$30,$B7) -> 5 | AF7: =AE7/SUM($AE$2:$AE1005) -> 0.023696682 | AG7: =B7&AE7 -> F5 | AH7: Ter matérias-primas acessíveis | AI7: =AF7 -> 0.023696682 | AJ7: =AE7 -> 5 | AK7: =VALUE(RIGHT(C7)) -> 0 | AL7: =VALUE(RIGHT(D7)) -> 0 | AM7: =VALUE(RIGHT(E7)) -> 0 | AN7: =VALUE(RIGHT(F7)) -> 0 | AO7: =VALUE(RIGHT(G7)) -> 0 | AP7: =VALUE(RIGHT(H7)) -> 1 | AQ7: =VALUE(RIGHT(I7)) -> 1 | AR7: =VALUE(RIGHT(J7)) -> 1 | ... BL7: =VALUE(RIGHT(AD7)) -> 0 | BN7: =LEFT(C7) | BO7: =LEFT(D7) | BP7: =LEFT(E7) | BQ7: =LEFT(F7) | BR7: =LEFT(G7) | BS7: =LEFT(H7) -> G | BT7: =LEFT(I7) -> F | BU7: =LEFT(J7) -> I | ... CO7: =LEFT(AD7)
A8: Ter montagem em poucas etapas | B8: G | I8: H3 | J8: I1 | K8: G3 | L8: K1 | M8: L3 | N8: M3 | O8: G1 | AE8: =SUMIFS($AK$2:$BL$30,$BN$2:$CO$30,$B8) -> 6 | AF8: =AE8/SUM($AE$2:$AE1006) -> 0.028436019 | AG8: =B8&AE8 -> G6 | AH8: Ter montagem em poucas etapas | AI8: =AF8 -> 0.028436019 | AJ8: =AE8 -> 6 | AK8: =VALUE(RIGHT(C8)) -> 0 | AL8: =VALUE(RIGHT(D8)) -> 0 | AM8: =VALUE(RIGHT(E8)) -> 0 | AN8: =VALUE(RIGHT(F8)) -> 0 | AO8: =VALUE(RIGHT(G8)) -> 0 | AP8: =VALUE(RIGHT(H8)) -> 0 | AQ8: =VALUE(RIGHT(I8)) -> 3 | AR8: =VALUE(RIGHT(J8)) -> 1 | ... BL8: =VALUE(RIGHT(AD8)) -> 0 | BN8: =LEFT(C8) | BO8: =LEFT(D8) | BP8: =LEFT(E8) | BQ8: =LEFT(F8) | BR8: =LEFT(G8) | BS8: =LEFT(H8) | BT8: =LEFT(I8) -> H | BU8: =LEFT(J8) -> I | ... CO8: =LEFT(AD8)
A9: Ter montagem rápida | B9: H | J9: H1 | K9: H3 | L9: K1 | M9: L3 | N9: M1 | O9: H1 | AE9: =SUMIFS($AK$2:$BL$30,$BN$2:$CO$30,$B9) -> 9 | AF9: =AE9/SUM($AE$2:$AE1007) -> 0.042654028 | AG9: =B9&AE9 -> H9 | AH9: Ter montagem rápida | AI9: =AF9 -> 0.042654028 | AJ9: =AE9 -> 9 | AK9: =VALUE(RIGHT(C9)) -> 0 | AL9: =VALUE(RIGHT(D9)) -> 0 | AM9: =VALUE(RIGHT(E9)) -> 0 | AN9: =VALUE(RIGHT(F9)) -> 0 | AO9: =VALUE(RIGHT(G9)) -> 0 | AP9: =VALUE(RIGHT(H9)) -> 0 | AQ9: =VALUE(RIGHT(I9)) -> 0 | AR9: =VALUE(RIGHT(J9)) -> 1 | ... BL9: =VALUE(RIGHT(AD9)) -> 0 | BN9: =LEFT(C9) | BO9: =LEFT(D9) | BP9: =LEFT(E9) | BQ9: =LEFT(F9) | BR9: =LEFT(G9) | BS9: =LEFT(H9) | BT9: =LEFT(I9) | BU9: =LEFT(J9) -> H | ... CO9: =LEFT(AD9)
A10: Ter aparência robusta | B10: I | K10: I3 | L10: I1 | M10: L3 | N10: M3 | O10: I1 | AE10: =SUMIFS($AK$2:$BL$30,$BN$2:$CO$30,$B10) -> 7 | AF10: =AE10/SUM($AE$2:$AE1008) -> 0.033175355 | AG10: =B10&AE10 -> I7 | AH10: Ter aparência robusta | AI10: =AF10 -> 0.033175355 | AJ10: =AE10 -> 7 | AK10: =VALUE(RIGHT(C10)) -> 0 | AL10: =VALUE(RIGHT(D10)) -> 0 | AM10: =VALUE(RIGHT(E10)) -> 0 | AN10: =VALUE(RIGHT(F10)) -> 0 | AO10: =VALUE(RIGHT(G10)) -> 0 | AP10: =VALUE(RIGHT(H10)) -> 0 | AQ10: =VALUE(RIGHT(I10)) -> 0 | AR10: =VALUE(RIGHT(J10)) -> 0 | ... BL10: =VALUE(RIGHT(AD10)) -> 0 | BN10: =LEFT(C10) | BO10: =LEFT(D10) | BP10: =LEFT(E10) | BQ10: =LEFT(F10) | BR10: =LEFT(G10) | BS10: =LEFT(H10) | BT10: =LEFT(I10) | BU10: =LEFT(J10) | ... CO10: =LEFT(AD10)
A11: Ter embalagem simples | B11: J | L11: K3 | M11: L5 | N11: M5 | O11: N1 | AE11: =SUMIFS($AK$2:$BL$30,$BN$2:$CO$30,$B11) -> 0 | AF11: =AE11/SUM($AE$2:$AE1009) -> 0 | AG11: =B11&AE11 -> J0 | AH11: Ter embalagem simples | AI11: =AF11 -> 0 | AJ11: =AE11 -> 0 | AK11: =VALUE(RIGHT(C11)) -> 0 | AL11: =VALUE(RIGHT(D11)) -> 0 | AM11: =VALUE(RIGHT(E11)) -> 0 | AN11: =VALUE(RIGHT(F11)) -> 0 | AO11: =VALUE(RIGHT(G11)) -> 0 | AP11: =VALUE(RIGHT(H11)) -> 0 | AQ11: =VALUE(RIGHT(I11)) -> 0 | AR11: =VALUE(RIGHT(J11)) -> 0 | ... BL11: =VALUE(RIGHT(AD11)) -> 0 | BN11: =LEFT(C11) | BO11: =LEFT(D11) | BP11: =LEFT(E11) | BQ11: =LEFT(F11) | BR11: =LEFT(G11) | BS11: =LEFT(H11) | BT11: =LEFT(I11) | BU11: =LEFT(J11) | ... CO11: =LEFT(AD11)
A12: Ter fácil desmontagem | B12: K | M12: L3 | N12: M1 | O12: K3 | AE12: =SUMIFS($AK$2:$BL$30,$BN$2:$CO$30,$B12) -> 11 | AF12: =AE12/SUM($AE$2:$AE1010) -> 0.052132701 | AG12: =B12&AE12 -> K11 | AH12: Ter fácil desmontagem | AI12: =AF12 -> 0.052132701 | AJ12: =AE12 -> 11 | AK12: =VALUE(RIGHT(C12)) -> 0 | AL12: =VALUE(RIGHT(D12)) -> 0 | AM12: =VALUE(RIGHT(E12)) -> 0 | AN12: =VALUE(RIGHT(F12)) -> 0 | AO12: =VALUE(RIGHT(G12)) -> 0 | AP12: =VALUE(RIGHT(H12)) -> 0 | AQ12: =VALUE(RIGHT(I12)) -> 0 | AR12: =VALUE(RIGHT(J12)) -> 0 | ... BL12: =VALUE(RIGHT(AD12)) -> 0 | BN12: =LEFT(C12) | BO12: =LEFT(D12) | BP12: =LEFT(E12) | BQ12: =LEFT(F12) | BR12: =LEFT(G12) | BS12: =LEFT(H12) | BT12: =LEFT(I12) | BU12: =LEFT(J12) | ... CO12: =LEFT(AD12)
A13: Ter capacidade para suportar as principais ferramentas | B13: L | N13: L1 | O13: L3 | AE13: =SUMIFS($AK$2:$BL$30,$BN$2:$CO$30,$B13) -> 37 | AF13: =AE13/SUM($AE$2:$AE1011) -> 0.17535545 | AG13: =B13&AE13 -> L37 | AH13: Ter capacidade para suportar as principais ferramentas | AI13: =AF13 -> 0.17535545 | AJ13: =AE13 -> 37 | AK13: =VALUE(RIGHT(C13)) -> 0 | AL13: =VALUE(RIGHT(D13)) -> 0 | AM13: =VALUE(RIGHT(E13)) -> 0 | AN13: =VALUE(RIGHT(F13)) -> 0 | AO13: =VALUE(RIGHT(G13)) -> 0 | AP13: =VALUE(RIGHT(H13)) -> 0 | AQ13: =VALUE(RIGHT(I13)) -> 0 | AR13: =VALUE(RIGHT(J13)) -> 0 | ... BL13: =VALUE(RIGHT(AD13)) -> 0 | BN13: =LEFT(C13) | BO13: =LEFT(D13) | BP13: =LEFT(E13) | BQ13: =LEFT(F13) | BR13: =LEFT(G13) | BS13: =LEFT(H13) | BT13: =LEFT(I13) | BU13: =LEFT(J13) | ... CO13: =LEFT(AD13)
A14: Ser compacto | B14: M | O14: M3 | AE14: =SUMIFS($AK$2:$BL$30,$BN$2:$CO$30,$B14) -> 23 | AF14: =AE14/SUM($AE$2:$AE1012) -> 0.10900474 | AG14: =B14&AE14 -> M23 | AH14: Ser compacto | AI14: =AF14 -> 0.10900474 | AJ14: =AE14 -> 23 | AK14: =VALUE(RIGHT(C14)) -> 0 | AL14: =VALUE(RIGHT(D14)) -> 0 | AM14: =VALUE(RIGHT(E14)) -> 0 | AN14: =VALUE(RIGHT(F14)) -> 0 | AO14: =VALUE(RIGHT(G14)) -> 0 | AP14: =VALUE(RIGHT(H14)) -> 0 | AQ14: =VALUE(RIGHT(I14)) -> 0 | AR14: =VALUE(RIGHT(J14)) -> 0 | ... BL14: =VALUE(RIGHT(AD14)) -> 0 | BN14: =LEFT(C14) | BO14: =LEFT(D14) | BP14: =LEFT(E14) | BQ14: =LEFT(F14) | BR14: =LEFT(G14) | BS14: =LEFT(H14) | BT14: =LEFT(I14) | BU14: =LEFT(J14) | ... CO14: =LEFT(AD14)
A15: Ter molde para a produção | B15: N | AE15: =SUMIFS($AK$2:$BL$30,$BN$2:$CO$30,$B15) -> 1 | AF15: =AE15/SUM($AE$2:$AE1013) -> 0.0047393365 | AG15: =B15&AE15 -> N1 | AH15: Ter molde para a produção | AI15: =AF15 -> 0.0047393365 | AJ15: =AE15 -> 1 | AK15: =VALUE(RIGHT(C15)) -> 0 | AL15: =VALUE(RIGHT(D15)) -> 0 | AM15: =VALUE(RIGHT(E15)) -> 0 | AN15: =VALUE(RIGHT(F15)) -> 0 | AO15: =VALUE(RIGHT(G15)) -> 0 | AP15: =VALUE(RIGHT(H15)) -> 0 | AQ15: =VALUE(RIGHT(I15)) -> 0 | AR15: =VALUE(RIGHT(J15)) -> 0 | ... BL15: =VALUE(RIGHT(AD15)) -> 0 | BN15: =LEFT(C15) | BO15: =LEFT(D15) | BP15: =LEFT(E15) | BQ15: =LEFT(F15) | BR15: =LEFT(G15) | BS15: =LEFT(H15) | BT15: =LEFT(I15) | BU15: =LEFT(J15) | ... CO15: =LEFT(AD15)
AE16: =SUMIFS($AK$2:$BL$30,$BN$2:$CO$30,#REF!) -> 0 | AF16: =AE16/SUM($AE$2:$AE1014) -> 0 | AG16: =#REF!&AE16 -> #REF! | AI16: =AF16 -> 0 | AJ16: =AE16 -> 0 | AK16: =VALUE(RIGHT(C16)) -> 0 | AL16: =VALUE(RIGHT(D16)) -> 0 | AM16: =VALUE(RIGHT(E16)) -> 0 | AN16: =VALUE(RIGHT(F16)) -> 0 | AO16: =VALUE(RIGHT(G16)) -> 0 | AP16: =VALUE(RIGHT(H16)) -> 0 | AQ16: =VALUE(RIGHT(I16)) -> 0 | AR16: =VALUE(RIGHT(J16)) -> 0 | ... BL16: =VALUE(RIGHT(AD16)) -> 0 | BN16: =LEFT(C16) | BO16: =LEFT(D16) | BP16: =LEFT(E16) | BQ16: =LEFT(F16) | BR16: =LEFT(G16) | BS16: =LEFT(H16) | BT16: =LEFT(I16) | BU16: =LEFT(J16) | ... CO16: =LEFT(AD16)
AE17: =SUMIFS($AK$2:$BL$30,$BN$2:$CO$30,#REF!) -> 0 | AF17: =AE17/SUM($AE$2:$AE1015) -> 0 | AG17: =#REF!&AE17 -> #REF! | AI17: =AF17 -> 0 | AJ17: =AE17 -> 0 | AK17: =VALUE(RIGHT(C17)) -> 0 | AL17: =VALUE(RIGHT(D17)) -> 0 | AM17: =VALUE(RIGHT(E17)) -> 0 | AN17: =VALUE(RIGHT(F17)) -> 0 | AO17: =VALUE(RIGHT(G17)) -> 0 | AP17: =VALUE(RIGHT(H17)) -> 0 | AQ17: =VALUE(RIGHT(I17)) -> 0 | AR17: =VALUE(RIGHT(J17)) -> 0 | ... BL17: =VALUE(RIGHT(AD17)) -> 0 | BN17: =LEFT(C17) | BO17: =LEFT(D17) | BP17: =LEFT(E17) | BQ17: =LEFT(F17) | BR17: =LEFT(G17) | BS17: =LEFT(H17) | BT17: =LEFT(I17) | BU17: =LEFT(J17) | ... CO17: =LEFT(AD17)
AE18: =SUMIFS($AK$2:$BL$30,$BN$2:$CO$30,#REF!) -> 0 | AF18: =AE18/SUM($AE$2:$AE1016) -> 0 | AG18: =#REF!&AE18 -> #REF! | AI18: =AF18 -> 0 | AJ18: =AE18 -> 0 | AK18: =VALUE(RIGHT(C18)) -> 0 | AL18: =VALUE(RIGHT(D18)) -> 0 | AM18: =VALUE(RIGHT(E18)) -> 0 | AN18: =VALUE(RIGHT(F18)) -> 0 | AO18: =VALUE(RIGHT(G18)) -> 0 | AP18: =VALUE(RIGHT(H18)) -> 0 | AQ18: =VALUE(RIGHT(I18)) -> 0 | AR18: =VALUE(RIGHT(J18)) -> 0 | ... BL18: =VALUE(RIGHT(AD18)) -> 0 | BN18: =LEFT(C18) | BO18: =LEFT(D18) | BP18: =LEFT(E18) | BQ18: =LEFT(F18) | BR18: =LEFT(G18) | BS18: =LEFT(H18) | BT18: =LEFT(I18) | BU18: =LEFT(J18) | ... CO18: =LEFT(AD18)
AE19: =SUMIFS($AK$2:$BL$30,$BN$2:$CO$30,#REF!) -> 0 | AF19: =AE19/SUM($AE$2:$AE1017) -> 0 | AG19: =#REF!&AE19 -> #REF! | AI19: =AF19 -> 0 | AJ19: =AE19 -> 0 | AK19: =VALUE(RIGHT(C19)) -> 0 | AL19: =VALUE(RIGHT(D19)) -> 0 | AM19: =VALUE(RIGHT(E19)) -> 0 | AN19: =VALUE(RIGHT(F19)) -> 0 | AO19: =VALUE(RIGHT(G19)) -> 0 | AP19: =VALUE(RIGHT(H19)) -> 0 | AQ19: =VALUE(RIGHT(I19)) -> 0 | AR19: =VALUE(RIGHT(J19)) -> 0 | ... BL19: =VALUE(RIGHT(AD19)) -> 0 | BN19: =LEFT(C19) | BO19: =LEFT(D19) | BP19: =LEFT(E19) | BQ19: =LEFT(F19) | BR19: =LEFT(G19) | BS19: =LEFT(H19) | BT19: =LEFT(I19) | BU19: =LEFT(J19) | ... CO19: =LEFT(AD19)
AE20: =SUMIFS($AK$2:$BL$30,$BN$2:$CO$30,#REF!) -> 0 | AF20: =AE20/SUM($AE$2:$AE1018) -> 0 | AG20: =#REF!&AE20 -> #REF! | AI20: =AF20 -> 0 | AJ20: =AE20 -> 0 | AK20: =VALUE(RIGHT(C20)) -> 0 | AL20: =VALUE(RIGHT(D20)) -> 0 | AM20: =VALUE(RIGHT(E20)) -> 0 | AN20: =VALUE(RIGHT(F20)) -> 0 | AO20: =VALUE(RIGHT(G20)) -> 0 | AP20: =VALUE(RIGHT(H20)) -> 0 | AQ20: =VALUE(RIGHT(I20)) -> 0 | AR20: =VALUE(RIGHT(J20)) -> 0 | ... BL20: =VALUE(RIGHT(AD20)) -> 0 | BN20: =LEFT(C20) | BO20: =LEFT(D20) | BP20: =LEFT(E20) | BQ20: =LEFT(F20) | BR20: =LEFT(G20) | BS20: =LEFT(H20) | BT20: =LEFT(I20) | BU20: =LEFT(J20) | ... CO20: =LEFT(AD20)
AE21: =SUMIFS($AK$2:$BL$30,$BN$2:$CO$30,#REF!) -> 0 | AF21: =AE21/SUM($AE$2:$AE1019) -> 0 | AG21: =#REF!&AE21 -> #REF! | AI21: =AF21 -> 0 | AJ21: =AE21 -> 0 | AK21: =VALUE(RIGHT(C21)) -> 0 | AL21: =VALUE(RIGHT(D21)) -> 0 | AM21: =VALUE(RIGHT(E21)) -> 0 | AN21: =VALUE(RIGHT(F21)) -> 0 | AO21: =VALUE(RIGHT(G21)) -> 0 | AP21: =VALUE(RIGHT(H21)) -> 0 | AQ21: =VALUE(RIGHT(I21)) -> 0 | AR21: =VALUE(RIGHT(J21)) -> 0 | ... BL21: =VALUE(RIGHT(AD21)) -> 0 | BN21: =LEFT(C21) | BO21: =LEFT(D21) | BP21: =LEFT(E21) | BQ21: =LEFT(F21) | BR21: =LEFT(G21) | BS21: =LEFT(H21) | BT21: =LEFT(I21) | BU21: =LEFT(J21) | ... CO21: =LEFT(AD21)
AE22: =SUMIFS($AK$2:$BL$30,$BN$2:$CO$30,#REF!) -> 0 | AF22: =AE22/SUM($AE$2:$AE1020) -> 0 | AG22: =#REF!&AE22 -> #REF! | AI22: =AF22 -> 0 | AJ22: =AE22 -> 0 | AK22: =VALUE(RIGHT(C22)) -> 0 | AL22: =VALUE(RIGHT(D22)) -> 0 | AM22: =VALUE(RIGHT(E22)) -> 0 | AN22: =VALUE(RIGHT(F22)) -> 0 | AO22: =VALUE(RIGHT(G22)) -> 0 | AP22: =VALUE(RIGHT(H22)) -> 0 | AQ22: =VALUE(RIGHT(I22)) -> 0 | AR22: =VALUE(RIGHT(J22)) -> 0 | ... BL22: =VALUE(RIGHT(AD22)) -> 0 | BN22: =LEFT(C22) | BO22: =LEFT(D22) | BP22: =LEFT(E22) | BQ22: =LEFT(F22) | BR22: =LEFT(G22) | BS22: =LEFT(H22) | BT22: =LEFT(I22) | BU22: =LEFT(J22) | ... CO22: =LEFT(AD22)
AE23: =SUMIFS($AK$2:$BL$30,$BN$2:$CO$30,#REF!) -> 0 | AF23: =AE23/SUM($AE$2:$AE1021) -> 0 | AG23: =#REF!&AE23 -> #REF! | AI23: =AF23 -> 0 | AJ23: =AE23 -> 0 | AK23: =VALUE(RIGHT(C23)) -> 0 | AL23: =VALUE(RIGHT(D23)) -> 0 | AM23: =VALUE(RIGHT(E23)) -> 0 | AN23: =VALUE(RIGHT(F23)) -> 0 | AO23: =VALUE(RIGHT(G23)) -> 0 | AP23: =VALUE(RIGHT(H23)) -> 0 | AQ23: =VALUE(RIGHT(I23)) -> 0 | AR23: =VALUE(RIGHT(J23)) -> 0 | ... BL23: =VALUE(RIGHT(AD23)) -> 0 | BN23: =LEFT(C23) | BO23: =LEFT(D23) | BP23: =LEFT(E23) | BQ23: =LEFT(F23) | BR23: =LEFT(G23) | BS23: =LEFT(H23) | BT23: =LEFT(I23) | BU23: =LEFT(J23) | ... CO23: =LEFT(AD23)
AE24: =SUMIFS($AK$2:$BL$30,$BN$2:$CO$30,#REF!) -> 0 | AF24: =AE24/SUM($AE$2:$AE1022) -> 0 | AG24: =#REF!&AE24 -> #REF! | AI24: =AF24 -> 0 | AJ24: =AE24 -> 0 | AK24: =VALUE(RIGHT(C24)) -> 0 | AL24: =VALUE(RIGHT(D24)) -> 0 | AM24: =VALUE(RIGHT(E24)) -> 0 | AN24: =VALUE(RIGHT(F24)) -> 0 | AO24: =VALUE(RIGHT(G24)) -> 0 | AP24: =VALUE(RIGHT(H24)) -> 0 | AQ24: =VALUE(RIGHT(I24)) -> 0 | AR24: =VALUE(RIGHT(J24)) -> 0 | ... BL24: =VALUE(RIGHT(AD24)) -> 0 | BN24: =LEFT(C24) | BO24: =LEFT(D24) | BP24: =LEFT(E24) | BQ24: =LEFT(F24) | BR24: =LEFT(G24) | BS24: =LEFT(H24) | BT24: =LEFT(I24) | BU24: =LEFT(J24) | ... CO24: =LEFT(AD24)
AE25: =SUMIFS($AK$2:$BL$30,$BN$2:$CO$30,#REF!) -> 0 | AF25: =AE25/SUM($AE$2:$AE1023) -> 0 | AG25: =#REF!&AE25 -> #REF! | AI25: =AF25 -> 0 | AJ25: =AE25 -> 0 | AK25: =VALUE(RIGHT(C25)) -> 0 | AL25: =VALUE(RIGHT(D25)) -> 0 | AM25: =VALUE(RIGHT(E25)) -> 0 | AN25: =VALUE(RIGHT(F25)) -> 0 | AO25: =VALUE(RIGHT(G25)) -> 0 | AP25: =VALUE(RIGHT(H25)) -> 0 | AQ25: =VALUE(RIGHT(I25)) -> 0 | AR25: =VALUE(RIGHT(J25)) -> 0 | ... BL25: =VALUE(RIGHT(AD25)) -> 0 | BN25: =LEFT(C25) | BO25: =LEFT(D25) | BP25: =LEFT(E25) | BQ25: =LEFT(F25) | BR25: =LEFT(G25) | BS25: =LEFT(H25) | BT25: =LEFT(I25) | BU25: =LEFT(J25) | ... CO25: =LEFT(AD25)
AE26: =SUMIFS($AK$2:$BL$30,$BN$2:$CO$30,#REF!) -> 0 | AF26: =AE26/SUM($AE$2:$AE1024) -> 0 | AG26: =#REF!&AE26 -> #REF! | AI26: =AF26 -> 0 | AJ26: =AE26 -> 0 | AK26: =VALUE(RIGHT(C26)) -> 0 | AL26: =VALUE(RIGHT(D26)) -> 0 | AM26: =VALUE(RIGHT(E26)) -> 0 | AN26: =VALUE(RIGHT(F26)) -> 0 | AO26: =VALUE(RIGHT(G26)) -> 0 | AP26: =VALUE(RIGHT(H26)) -> 0 | AQ26: =VALUE(RIGHT(I26)) -> 0 | AR26: =VALUE(RIGHT(J26)) -> 0 | ... BL26: =VALUE(RIGHT(AD26)) -> 0 | BN26: =LEFT(C26) | BO26: =LEFT(D26) | BP26: =LEFT(E26) | BQ26: =LEFT(F26) | BR26: =LEFT(G26) | BS26: =LEFT(H26) | BT26: =LEFT(I26) | BU26: =LEFT(J26) | ... CO26: =LEFT(AD26)
AE27: =SUMIFS($AK$2:$BL$30,$BN$2:$CO$30,LEFT(#REF!)) -> 0 | AF27: =AE27/SUM($AE$2:$AE1025) -> 0 | AG27: =#REF!&AE27 -> #REF! | AI27: =AF27 -> 0 | AJ27: =AE27 -> 0 | AK27: =VALUE(RIGHT(C27)) -> 0 | AL27: =VALUE(RIGHT(D27)) -> 0 | AM27: =VALUE(RIGHT(E27)) -> 0 | AN27: =VALUE(RIGHT(F27)) -> 0 | AO27: =VALUE(RIGHT(G27)) -> 0 | AP27: =VALUE(RIGHT(H27)) -> 0 | AQ27: =VALUE(RIGHT(I27)) -> 0 | AR27: =VALUE(RIGHT(J27)) -> 0 | ... BL27: =VALUE(RIGHT(AD27)) -> 0 | BN27: =LEFT(C27) | BO27: =LEFT(D27) | BP27: =LEFT(E27) | BQ27: =LEFT(F27) | BR27: =LEFT(G27) | BS27: =LEFT(H27) | BT27: =LEFT(I27) | BU27: =LEFT(J27) | ... CO27: =LEFT(AD27)
AE28: =SUMIFS($AK$2:$BL$30,$BN$2:$CO$30,LEFT(#REF!)) -> 0 | AF28: =AE28/SUM($AE$2:$AE1026) -> 0 | AG28: =#REF!&AE28 -> #REF! | AI28: =AF28 -> 0 | AJ28: =AE28 -> 0 | AK28: =VALUE(RIGHT(C28)) -> 0 | AL28: =VALUE(RIGHT(D28)) -> 0 | AM28: =VALUE(RIGHT(E28)) -> 0 | AN28: =VALUE(RIGHT(F28)) -> 0 | AO28: =VALUE(RIGHT(G28)) -> 0 | AP28: =VALUE(RIGHT(H28)) -> 0 | AQ28: =VALUE(RIGHT(I28)) -> 0 | AR28: =VALUE(RIGHT(J28)) -> 0 | ... BL28: =VALUE(RIGHT(AD28)) -> 0 | BN28: =LEFT(C28) | BO28: =LEFT(D28) | BP28: =LEFT(E28) | BQ28: =LEFT(F28) | BR28: =LEFT(G28) | BS28: =LEFT(H28) | BT28: =LEFT(I28) | BU28: =LEFT(J28) | ... CO28: =LEFT(AD28)
AE29: =SUMIFS($AK$2:$BL$30,$BN$2:$CO$30,LEFT(#REF!)) -> 0 | AF29: =AE29/SUM($AE$2:$AE1027) -> 0 | AG29: =#REF!&AE29 -> #REF! | AI29: =AF29 -> 0 | AJ29: =AE29 -> 0 | AK29: =VALUE(RIGHT(C29)) -> 0 | AL29: =VALUE(RIGHT(D29)) -> 0 | AM29: =VALUE(RIGHT(E29)) -> 0 | AN29: =VALUE(RIGHT(F29)) -> 0 | AO29: =VALUE(RIGHT(G29)) -> 0 | AP29: =VALUE(RIGHT(H29)) -> 0 | AQ29: =VALUE(RIGHT(I29)) -> 0 | AR29: =VALUE(RIGHT(J29)) -> 0 | ... BL29: =VALUE(RIGHT(AD29)) -> 0 | BN29: =LEFT(C29) | BO29: =LEFT(D29) | BP29: =LEFT(E29) | BQ29: =LEFT(F29) | BR29: =LEFT(G29) | BS29: =LEFT(H29) | BT29: =LEFT(I29) | BU29: =LEFT(J29) | ... CO29: =LEFT(AD29)
AE30: =SUMIFS($AK$2:$BL$30,$BN$2:$CO$30,LEFT(#REF!)) -> 0 | AF30: =AE30/SUM($AE$2:$AE1028) -> 0 | AG30: =#REF!&AE30 -> #REF! | AI30: =AF30 -> 0 | AJ30: =AE30 -> 0 | AK30: =VALUE(RIGHT(C30)) -> 0 | AL30: =VALUE(RIGHT(D30)) -> 0 | AM30: =VALUE(RIGHT(E30)) -> 0 | AN30: =VALUE(RIGHT(F30)) -> 0 | AO30: =VALUE(RIGHT(G30)) -> 0 | AP30: =VALUE(RIGHT(H30)) -> 0 | AQ30: =VALUE(RIGHT(I30)) -> 0 | AR30: =VALUE(RIGHT(J30)) -> 0 | ... BL30: =VALUE(RIGHT(AD30)) -> 0 | BN30: =LEFT(C30) | BO30: =LEFT(D30) | BP30: =LEFT(E30) | BQ30: =LEFT(F30) | BR30: =LEFT(G30) | BS30: =LEFT(H30) | BT30: =LEFT(I30) | BU30: =LEFT(J30) | ... CO30: =LEFT(AD30)
AG31: =B16&AE31 | AI31: =AF31 | AJ31: =AE31
AG32: =B17&AE32 | AI32: =AF32 | AJ32: =AE32
AG33: =B18&AE33 | AI33: =AF33 | AJ33: =AE33
AG34: =B19&AE34 | AI34: =AF34 | AJ34: =AE34
AG35: =B20&AE35 | AI35: =AF35 | AJ35: =AE35
AG36: =B21&AE36 | AI36: =AF36 | AJ36: =AE36
AG37: =B22&AE37 | AI37: =AF37 | AJ37: =AE37
AG38: =B23&AE38 | AI38: =AF38 | AJ38: =AE38
AG39: =B24&AE39 | AI39: =AF39 | AJ39: =AE39
AG40: =B25&AE40 | AI40: =AF40 | AJ40: =AE40
...

Sheet 6. Pareto
A1: PARETO E LIKERT | C1: Total | D1: % | E1: Acumulado | F1: LINKERT
A2: =VLOOKUP(B2,'5.Mudge'!$AG:$AH,2,false) -> Ter capacidade para suportar as principais ferramentas | B2: L37 | C2: =VLOOKUP(B2,'5.Mudge'!$AG:$AJ,4,false) -> 37 | D2: =VLOOKUP(B2,'5.Mudge'!$AG:$AJ,3,false) -> 0.17535545 | E2: =D2 -> 0.17535545 | F2: 5
A3: =VLOOKUP(B3,'5.Mudge'!$AG:$AH,2,false) -> Ter compartimentos | B3: E32 | C3: =VLOOKUP(B3,'5.Mudge'!$AG:$AJ,4,false) -> 32 | D3: =VLOOKUP(B3,'5.Mudge'!$AG:$AJ,3,false) -> 0.15165877 | E3: =E2+D3 -> 0.32701422 | F3: 5
A4: =VLOOKUP(B4,'5.Mudge'!$AG:$AH,2,false) -> Ser de fácil movimentação | B4: B31 | C4: =VLOOKUP(B4,'5.Mudge'!$AG:$AJ,4,false) -> 31 | D4: =VLOOKUP(B4,'5.Mudge'!$AG:$AJ,3,false) -> 0.14691943 | E4: =E3+D4 -> 0.47393365 | F4: 5
A5: =VLOOKUP(B5,'5.Mudge'!$AG:$AH,2,false) -> Ser durável | B5: C24 | C5: =VLOOKUP(B5,'5.Mudge'!$AG:$AJ,4,false) -> 24 | D5: =VLOOKUP(B5,'5.Mudge'!$AG:$AJ,3,false) -> 0.11374408 | E5: =E4+D5 -> 0.58767773 | F5: 4
A6: =VLOOKUP(B6,'5.Mudge'!$AG:$AH,2,false) -> Ser compacto | B6: M23 | C6: =VLOOKUP(B6,'5.Mudge'!$AG:$AJ,4,false) -> 23 | D6: =VLOOKUP(B6,'5.Mudge'!$AG:$AJ,3,false) -> 0.10900474 | E6: =E5+D6 -> 0.69668246 | F6: 4
A7: =VLOOKUP(B7,'5.Mudge'!$AG:$AH,2,false) -> Ter manutenção simples | B7: D13 | C7: =VLOOKUP(B7,'5.Mudge'!$AG:$AJ,4,false) -> 13 | D7: =VLOOKUP(B7,'5.Mudge'!$AG:$AJ,3,false) -> 0.061611374 | E7: =E6+D7 -> 0.75829384 | F7: 3
A8: =VLOOKUP(B8,'5.Mudge'!$AG:$AH,2,false) -> Ter bom custo benefício | B8: A12 | C8: =VLOOKUP(B8,'5.Mudge'!$AG:$AJ,4,false) -> 12 | D8: =VLOOKUP(B8,'5.Mudge'!$AG:$AJ,3,false) -> 0.056872038 | E8: =E7+D8 -> 0.81516588 | F8: 3
A9: =VLOOKUP(B9,'5.Mudge'!$AG:$AH,2,false) -> Ter fácil desmontagem | B9: K11 | C9: =VLOOKUP(B9,'5.Mudge'!$AG:$AJ,4,false) -> 11 | D9: =VLOOKUP(B9,'5.Mudge'!$AG:$AJ,3,false) -> 0.052132701 | E9: =E8+D9 -> 0.86729858 | F9: 3
A10: =VLOOKUP(B10,'5.Mudge'!$AG:$AH,2,false) -> Ter montagem rápida | B10: H9 | C10: =VLOOKUP(B10,'5.Mudge'!$AG:$AJ,4,false) -> 9 | D10: =VLOOKUP(B10,'5.Mudge'!$AG:$AJ,3,false) -> 0.042654028 | E10: =E9+D10 -> 0.90995261 | F10: 3
A11: =VLOOKUP(B11,'5.Mudge'!$AG:$AH,2,false) -> Ter aparência robusta | B11: I7 | C11: =VLOOKUP(B11,'5.Mudge'!$AG:$AJ,4,false) -> 7 | D11: =VLOOKUP(B11,'5.Mudge'!$AG:$AJ,3,false) -> 0.033175355 | E11: =E10+D11 -> 0.94312796 | F11: 2
A12: =VLOOKUP(B12,'5.Mudge'!$AG:$AH,2,false) -> Ter montagem em poucas etapas | B12: G6 | C12: =VLOOKUP(B12,'5.Mudge'!$AG:$AJ,4,false) -> 6 | D12: =VLOOKUP(B12,'5.Mudge'!$AG:$AJ,3,false) -> 0.028436019 | E12: =E11+D12 -> 0.97156398 | F12: 2
A13: =VLOOKUP(B13,'5.Mudge'!$AG:$AH,2,false) -> Ter matérias-primas acessíveis | B13: F5 | C13: =VLOOKUP(B13,'5.Mudge'!$AG:$AJ,4,false) -> 5 | D13: =VLOOKUP(B13,'5.Mudge'!$AG:$AJ,3,false) -> 0.023696682 | E13: =E12+D13 -> 0.99526066 | F13: 2
A14: =VLOOKUP(B14,'5.Mudge'!$AG:$AH,2,false) -> Ter molde para a produção | B14: N1 | C14: =VLOOKUP(B14,'5.Mudge'!$AG:$AJ,4,false) -> 1 | D14: =VLOOKUP(B14,'5.Mudge'!$AG:$AJ,3,false) -> 0.0047393365 | E14: =E13+D14 -> 1 | F14: 1
A15: =VLOOKUP(B15,'5.Mudge'!$AG:$AH,2,false) -> Ter embalagem simples | B15: J0 | C15: =VLOOKUP(B15,'5.Mudge'!$AG:$AJ,4,false) -> 0 | D15: =VLOOKUP(B15,'5.Mudge'!$AG:$AJ,3,false) -> 0 | E15: =E14+D15 -> 1 | F15: 1

Sheet 7. QFD Final
U3: 𒊹
T5: 𒊹 | V5: Ｏ
S7: 𒊹 | U7: 𒊹 | W7: ▼
R9: 𒊹 | T9: 𒊹 | V9: Ｏ | X9: Ｏ
B10: House of Quality
Q11: Ｏ | S11: 𒊹 | U11: 𒊹 | W11: Ｏ | Y11: 𒊹
P13: 𒊹 | R13: Ｏ | T13: ▼ | V13: Ｏ | X13: 𒊹 | Z13: Ｏ
O15: 𒊹 | Q15: 𒊹 | S15: Ｏ | U15: Ｏ | W15: ▽ | Y15: ▼ | AA15: Ｏ
N17: 𒊹 | P17: Ｏ | R17: ▽ | T17: ▼ | V17: 𒊹 | X17: Ｏ | Z17: Ｏ | AB17: Ｏ
M19: Ｏ | O19: 𒊹 | Q19: Ｏ | S19: ▽ | U19: 𒊹 | W19: Ｏ | Y19: Ｏ | AA19: Ｏ | AC19: 𒊹
L21: ▼ | N21: Ｏ | P21: ▼ | R21: Ｏ | T21: 𒊹 | V21: Ｏ | X21: Ｏ | Z21: Ｏ | AB21: 𒊹 | AD21: Ｏ
K23: 𒊹 | M23: 𒊹 | O23: Ｏ | Q23: Ｏ | S23: Ｏ | U23: 𒊹 | W23: Ｏ | Y23: ▼ | AA23: ▽ | AC23: 𒊹 | AE23: Ｏ
J25: 𒊹 | L25: Ｏ | N25: 𒊹 | P25: Ｏ | R25: Ｏ | T25: ▽ | V25: Ｏ | X25: 𒊹 | Z25: ▽ | AB25: 𒊹 | AD25: Ｏ | AF25: Ｏ
I27: Ｏ | K27: ▼ | M27: Ｏ | O27: 𒊹 | Q27: 𒊹 | S27: Ｏ | U27: Ｏ | W27: Ｏ | Y27: 𒊹 | AA27: Ｏ | AC27: 𒊹 | AE27: 𒊹 | AG27: Ｏ
H29: Ｏ | J29: 𒊹 | L29: Ｏ | N29: 𒊹 | P29: 𒊹 | R29: 𒊹 | T29: Ｏ | V29: Ｏ | X29: Ｏ | Z29: Ｏ | AB29: ▽ | AD29: Ｏ | AF29: Ｏ | AH29: ▽
G31: Ｏ | I31: Ｏ | K31: 𒊹 | M31: Ｏ | O31: ▽ | Q31: Ｏ | S31: Ｏ | U31: Ｏ | W31: 𒊹 | Y31: Ｏ | AA31: Ｏ | AC31: ▽ | AE31: Ｏ | AG31: Ｏ | AI31: ▽
F33: Ｏ | H33: ▽ | J33: 𒊹 | L33: Ｏ | N33: ▽ | P33: ▽ | R33: Ｏ | T33: 𒊹 | V33: Ｏ | X33: 𒊹 | Z33: ▽ | AB33: ▽ | AD33: Ｏ | AF33: 𒊹 | AH33: Ｏ | AJ33: 𒊹 | AM33: Improvement Direction
B35: Customer Requirements | D35: Importance | E35: 1. | G35: 2. | I35: 3. | K35: 4. | M35: 5. | O35: 6. | Q35: 7. | S35: 8. | U35: 9. | W35: 10. | Y35: 11. | AA35: 12. | AC35: 13. | AE35: 14. | AG35: 15. | AI35: 16. | AK35: 17. | AM35: Customer Competitive Assessment | AS35: Lista de requisitos do produto: | AT35: {=TRANSPOSE(E51:AL51)} -> 121
AM36: 1 Pior | AN36: 2 | AO36: 3 | AP36: 4 | AQ36: 5 Melhor | AS36: 1. Custo-alvo de fabricação (R$)
B37: Ter capacidade para suportar as principais ferramentas | D37: 5 | E37: 3 | G37: 5 | I37: 1 | K37: 0 | M37: 5 | O37: 3 | Q37: 1 | S37: 5 | U37: 1 | W37: 0 | Y37: 0 | AA37: 0 | AC37: 0 | AE37: 5 | AG37: 0 | AI37: 5 | AK37: 3 | AM37: A | AN37: B | AO37: D | AP37: N | AQ37: C | AS37: 2. Peso máximo (Kg) | AT37: 112
B38: Ter compartimentos | D38: 5 | E38: 3 | G38: 3 | I38: 3 | K38: 3 | M38: 5 | O38: 5 | Q38: 3 | S38: 5 | U38: 3 | W38: 0 | Y38: 3 | AA38: 3 | AC38: 5 | AE38: 3 | AG38: 0 | AI38: 3 | AK38: 1 | AM38: B | AN38: A | AO38: D | AP38: C | AQ38: N | AS38: 3. Taxa de falhas %
B39: Ser de fácil movimentação | D39: 5 | E39: 1 | G39: 5 | I39: 3 | K39: 1 | M39: 1 | O39: 5 | Q39: 3 | S39: 5 | U39: 1 | W39: 0 | Y39: 0 | AA39: 0 | AC39: 3 | AE39: 5 | AG39: 3 | AI39: 1 | AK39: 0 | AM39: D | AN39: B | AO39: A | AP39: C | AQ39: N | AS39: 4.Tempo médio para reparo (dias) | AT39: 80
B40: Ser durável | D40: 4 | E40: 5 | G40: 5 | I40: 5 | K40: 1 | M40: 1 | O40: 1 | Q40: 5 | S40: 3 | U40: 0 | W40: 3 | Y40: 5 | AA40: 0 | AC40: 0 | AE40: 1 | AG40: 5 | AI40: 0 | AK40: 1 | AM40: B | AN40: A | AO40: C | AP40: N | AQ40: D | AS40: 5. Número de compartimentos (qte)
B41: Ser compacto | D41: 4 | E41: 1 | G41: 3 | I41: 1 | K41: 3 | M41: 5 | O41: 5 | Q41: 0 | S41: 3 | U41: 3 | W41: 0 | Y41: 0 | AA41: 5 | AC41: 1 | AE41: 1 | AG41: 1 | AI41: 5 | AK41: 0 | AM41: C | AN41: N | AO41: D | AP41: B | AQ41: A | AS41: 6. Dimensões e volume de cada compartimento. (cm) | AT41: 101
B42: Ter manutenção simples | D42: 3 | E42: 3 | G42: 0 | I42: 0 | K42: 5 | M42: 3 | O42: 1 | Q42: 5 | S42: 5 | U42: 5 | W42: 0 | Y42: 0 | AA42: 0 | AC42: 1 | AE42: 0 | AG42: 1 | AI42: 0 | AK42: 3 | AM42: B | AN42: A | AO42: C | AP42: D | AQ42: N | AS42: 7. Diponibilidade de materiais utilizados (%)
B43: Ter bom custo benefício | D43: 3 | E43: 5 | G43: 1 | I43: 0 | K43: 3 | M43: 5 | O43: 1 | Q43: 5 | S43: 1 | U43: 3 | W43: 1 | Y43: 3 | AA43: 5 | AC43: 0 | AE43: 0 | AG43: 3 | AI43: 1 | AK43: 5 | AM43: D | AN43: C | AO43: A | AP43: N | AQ43: B | AS43: 8. Número reduzido de componentes (qte) | AT43: 151
B44: Ter fácil desmontagem | D44: 3 | E44: 3 | G44: 0 | I44: 1 | K44: 5 | M44: 5 | O44: 3 | Q44: 0 | S44: 5 | U44: 5 | W44: 0 | Y44: 0 | AA44: 0 | AC44: 5 | AE44: 0 | AG44: 1 | AI44: 1 | AK44: 0 | AM44: B | AN44: D | AO44: A | AP44: C | AQ44: N | AS44: 9. Tempo total de montagem (minutos)
B45: Ter montagem rápida | D45: 3 | E45: 1 | G45: 1 | I45: 3 | K45: 1 | M45: 5 | O45: 1 | Q45: 0 | S45: 5 | U45: 5 | W45: 1 | Y45: 0 | AA45: 0 | AC45: 3 | AE45: 1 | AG45: 1 | AI45: 0 | AK45: 1 | AM45: D | AN45: C | AO45: A | AP45: N | AQ45: B | AS45: 10. Acabamento superficial apropriado. | AT45: 110
B46: Ter aparência robusta | D46: 2 | E46: 3 | G46: 3 | I46: 1 | K46: 0 | M46: 3 | O46: 0 | Q46: 1 | S46: 1 | U46: 0 | W46: 1 | Y46: 5 | AA46: 0 | AC46: 1 | AE46: 0 | AG46: 5 | AI46: 1 | AK46: 0 | AM46: C | AN46: A | AO46: B | AP46: N | AQ46: D | AS46: 11. Seleção de cores e texturas que reforcem a percepção de robustez (qte)
B47: Ter montagem em poucas etapas | D47: 2 | E47: 1 | G47: 1 | I47: 3 | K47: 5 | M47: 3 | O47: 0 | Q47: 0 | S47: 5 | U47: 5 | W47: 0 | Y47: 0 | AA47: 0 | AC47: 5 | AE47: 1 | AG47: 3 | AI47: 1 | AK47: 5 | AM47: C | AN47: D | AO47: N | AP47: A | AQ47: B | AS47: 12. Custo da embalagem (R$) | AT47: 103
B48: Ter matérias-primas acessíveis | D48: 2 | E48: 5 | G48: 0 | I48: 0 | K48: 5 | M48: 0 | O48: 1 | Q48: 5 | S48: 0 | U48: 1 | W48: 3 | Y48: 0 | AA48: 0 | AC48: 0 | AE48: 5 | AG48: 1 | AI48: 0 | AK48: 0 | AM48: D | AN48: C | AO48: N | AP48: A | AQ48: B | AS48: 13. Número reduzido de passos para desmontagem (qte)
B49: Ter molde para a produção | D49: 1 | E49: 3 | G49: 0 | I49: 1 | K49: 3 | M49: 5 | O49: 1 | Q49: 3 | S49: 5 | U49: 5 | W49: 1 | Y49: 0 | AA49: 0 | AC49: 1 | AE49: 0 | AG49: 1 | AI49: 3 | AK49: 5 | AM49: B | AN49: A | AO49: C | AP49: N | AQ49: D | AS49: 14. Capacidade de carga máxima (Kg) | AT49: 164
B50: Ter embalagem simples | D50: 1 | E50: 5 | G50: 1 | I50: 0 | K50: 0 | M50: 1 | O50: 0 | Q50: 3 | S50: 0 | U50: 1 | W50: 3 | Y50: 0 | AA50: 5 | AC50: 0 | AE50: 5 | AG50: 0 | AI50: 1 | AK50: 0 | AM50: C | AN50: N | AO50: D | AP50: B | AQ50: A | AS50: 15. Resistência estrutural a cargas e impactos (G)
B51: Technical Importance: Absolute | E51: =SUMPRODUCT($D$37:$D$50,E37:E50) -> 121 | G51: =SUMPRODUCT($D$37:$D$50,G37:G50) -> 112 | I51: =SUMPRODUCT($D$37:$D$50,I37:I50) -> 80 | K51: =SUMPRODUCT($D$37:$D$50,K37:K50) -> 101 | M51: =SUMPRODUCT($D$37:$D$50,M37:M50) -> 151 | O51: =SUMPRODUCT($D$37:$D$50,O37:O50) -> 110 | Q51: =SUMPRODUCT($D$37:$D$50,Q37:Q50) -> 103 | S51: =SUMPRODUCT($D$37:$D$50,S37:S50) -> 164 | U51: =SUMPRODUCT($D$37:$D$50,U37:U50) -> 109 | W51: =SUMPRODUCT($D$37:$D$50,W37:W50) -> 30 | Y51: =SUMPRODUCT($D$37:$D$50,Y37:Y50) -> 54 | AA51: =SUMPRODUCT($D$37:$D$50,AA37:AA50) -> 55 | AC51: =SUMPRODUCT($D$37:$D$50,AC37:AC50) -> 84 | AE51: =SUMPRODUCT($D$37:$D$50,AE37:AE50) -> 93 | AG51: =SUMPRODUCT($D$37:$D$50,AG37:AG50) -> 76 | AI51: =SUMPRODUCT($D$37:$D$50,AI37:AI50) -> 79 | AK51: =SUMPRODUCT($D$37:$D$50,AK37:AK50) -> 66 | AM51: Legenda: | AS51: 16. Dimensões externas máximas (altura, largura, profundidade em cm). | AT51: 109
B52: Technical Importance: Relative | E52: 3 | G52: 4 | I52: 11 | K52: 8 | M52: 2 | O52: 5 | Q52: 7 | S52: 1 | U52: 6 | W52: 17 | Y52: 16 | AA52: 15 | AC52: 10 | AE52: 9 | AG52: 13 | AI52: 12 | AK52: 14 | AM52: N | AN52: Nosso produto | AS52: 17. Especificações do molde (que se tornará um recurso de fabricação).
B53: Technical Importance: Benchmarking | E53: A = | G53: =5*(1+2+3)+4*(2+5)+3*(2+3+3+3)+2*(2+4+4)+1*(2+5) -> 118 | I53: B = | K53: =5*(2+1+2)+4*(1+4)+3*(1+5+1+5)+2*(3+5+5)+1*(1+4) -> 112 | M53: C = | O53: =5*(5+4+4)+4*(3+1)+3*(3+2+4+2)+2*(1+1+2)+1*(3+1) -> 126 | Q53: D = | S53: =5*(3+3+1)+4*(5+3)+3*(4+1+2+1)+2*(5+2+1)+1*(5+3) -> 115 | U53: N = | W53: =5*(4+5+5)+4*(4+2)+3*(5+4+5+4)+2*(4+3+3)+1*(4+2) -> 174 | AM53: A | AN53: ="Empresa - "&AM53 -> Empresa - A | AT53: 30
AM54: B | AN54: ="Empresa - "&AM54 -> Empresa - B
D55: 𒊹 - Fortemente positivo | J55: 𒊹 | AM55: C | AN55: ="Empresa - "&AM55 -> Empresa - C | AT55: 54
D56: Ｏ - Positivo | J56: Ｏ | AM56: D | AN56: ="Empresa - "&AM56 -> Empresa - D
D57: ▽ - Negativo | J57: ▽ | AT57: 55
...

Sheet 8. Funções
A1: Nome do Requisito do Produto | B1: Unidade | C1: Objetivo | D1: Sensores | E1: Observações | G1: Função Global
A2: Custo-alvo de fabricação (R$) (-) | B2: Reais (R$) | C2: ≤$1.500,00 | D2: Todos os custos do produto | E2: Incluir custos diretos e indiretos. | G2: Armazenar ferramentas
A3: Peso máximo (Kg) (-) | B3: Quilograma (Kg) | C3: ≤ 20 | D3: Balança / Dinamômetro | E3: O peso deve ser baixo para fácil transporte manual. | G3: Funções técnicas
A4: Taxa de falhas (%) (-) | B4: Porcentagem (%) | C4: ≤ 5% | D4: Registros de uso / Testes de resistência | E4: Garantir confiabilidade e segurança no uso diário. | G4: Movimentar ferramentas
A5: Tempo médio para reparo (dias) (-) | B5: Dias | C5: ≤ 2 | D5: Relato de operadores / Tempo cronometrado | E5: Reparos rápidos devem ser possíveis em campo. | G5: Armazenar ferramentas
A6: Número de compartimentos (qte) (+) | B6: Quantidade (n°) | C6: ≥ 4 | D6: Verificação de projeto | E6: Os compartimentos devem acomodar ferramentas básicas. | G6: Organizar ferramentas
A7: Dimensões e volume de cada compartimento. (cm) (+) | B7: Centímetros (cm) | C7: Volume suficiente, máx. 25x25x25 | D7: Trena / Modelagem 3D | E7: Os compartimentos devem ser ergonômicos. | G7: Bloquear movimentação
A8: Disponibilidade de materiais utilizados (%) (+) | B8: Porcentagem (%) | C8: ≥ 70% de materiais disponíveis | D8: Verificação do projeto detalhado | E8: Usar materiais comuns e de fácil acesso. | G8: Travar módulos
A9: Número reduzido de componentes (qte) (-) | B9: Quantidade (n°) | C9: ≤ 10 | D9: Verificação do projeto | E9: Facilita montagem e manutenção. | G9: Bloquear acesso
A10: Tempo total de montagem (minutos) (-) | B10: Tempo (min) | C10: ≤ 5 | D10: Cronômetro | E10: O projeto deve permitir montagem simples e rápida. | G10: Encaixar ferramentas
A11: Acabamento superficial apropriado (+) | B11: Satisfação do cliente (NPS) | C11: Adequado ao uso em obras | D11: Avaliação visual / Toque | E11: Resistência à sujeira e desgaste. | G11: Juntar peças
A12: Seleção de cores e texturas que reforcem a percepção de robustez (qte) (+) | B12: Quantidade (n°) | C12: ≥ 2 cores/texturas | D12: Verificação visual | E12: Cores como cinza, preto ou laranja industrial.
A13: Custo da embalagem (R$) (-) | B13: Reais (R$) | C13: ≤ R$20,00 | D13: Verificação de materiais e fornecedores | E13: Embalagem funcional e econômica.
A14: Número reduzido de passos para desmontagem (qte) (-) | B14: Quantidade (n°) | C14: ≤ 5 | D14: Verificação de projeto e testes | E14: Simples desmontagem para transporte/armazenamento
A15: Capacidade de carga máxima (Kg) (+) | B15: Quilograma (Kg) | C15: ≥ 30 | D15: Dinamômetro | E15: Deve suportar o peso típico de ferramentas de obra.
A16: Resistência estrutural a cargas e impactos (G) (+) | B16: Força G (G) | C16: ≥ 3G | D16: Acelerômetro / Testes de impacto (drop test) | E16: Garantir resistência ao transporte em terreno irregular.
A17: Dimensões externas máximas (altura, largura, profundidade em cm) (-) | B17: Centímetros (cm) | C17: ≤ 80x50x50 | D17: Trena / Modelagem CAD | E17: Compatível com portas e elevadores de quitinetes.
A18: Especificações do molde (que se tornará um recurso de fabricação) (+) | B18: velocidade de produção (peças/dia) | C18: ≥ 3 moldes | D18: Verificação de projeto detalhado | E18: Facilitar replicação e produção em escala./
A33: Nome do Requisito do Produto | B33: Unidade | C33: Objetivo | D33: Sensores | E33: Observações
A34: Custo-alvo de fabricação (R$) (-) | B34: Reais (R$) | C34: ≤$1.500,00 | D34: Todos os custos do produto | E34: Incluir custos diretos e indiretos.
A35: Peso máximo (Kg) (-) | B35: Quilograma (Kg) | C35: ≤ 20 | D35: Balança / Dinamômetro | E35: O peso deve ser baixo para fácil transporte manual.
A36: Tempo médio para reparo (dias) (-) | B36: Dias | C36: ≤ 2 | D36: Relato de operadores / Tempo cronometrado | E36: Reparos rápidos devem ser possíveis em campo.
A37: Tempo total de montagem (minutos) (-) | B37: Tempo (min) | C37: ≤ 5 | D37: Cronômetro | E37: O projeto deve permitir montagem simples e rápida.
... A41: Resistência estrutural a cargas e impactos (G) (+) | B41: Força G (G) | C41: ≥ 3G | D41: Acelerômetro / Testes de impacto (drop test) | E41: Garantir resistência ao transporte em terreno irregular.
A46: Material | B46: Custo estimado | C46: Comentário | E46: Claro! Abaixo está a mesma tabela, agora sem os emojis:
A47: Aço galvanizado (SAE 1008/1010) | B47: Baixo (R$5–10/kg) | C47: Muito usado na indústria, ótimo custo-benefício.
A48: Aço SAE 1020 | B48: Baixo a moderado (R$8–14/kg) | C48: Preço competitivo, fácil conformação. | E48: Seleção de Materiais por Critério Técnico
A49: Alumínio 6061-T6 | B49: Moderado a alto (R$30–60/kg) | C49: Leve e resistente, mas preço sensível ao dólar.
E50: Material | F50: Resistência | G50: Durabilidade | H50: Peso (densidade) | I50: Reciclabilidade | J50: Disponibilidade | K50: Custo | L50: Processabilidade | M50: Aplicação recomendada
E51: Aço SAE 1020 | F51: Boa para aplicações estruturais leves | G51: Adequada com proteção superficial (galvanização ou pintura) | H51: ~7,8 g/cm³ | I51: Alta, 100% reciclável | J51: Ampla, padrão industrial | K51: Baixo | L51: Excelente para corte, dobra e solda | M51: Corpo do produto e reforços estruturais
E52: Alumínio 6061-T6 | F52: Boa relação resistência/peso | G52: Boa resistência à corrosão | H52: 2,7 g/cm³ | I52: Alta, com baixa perda de propriedades | J52: Boa | K52: Moderado | L52: Boa usinabilidade e soldabilidade; pode exigir anodização | M52: Versões premium com foco em leveza
E53: Aço galvanizado SAE 1008/1010 | F53: Suficiente para aplicações leves | G53: Boa com galvanização contínua | H53: ~7,8 g/cm³ | I53: Total | J53: Excelente | K53: Baixíssimo | L53: Ótima para corte a laser, dobra e pintura | M53: Estrutura econômica com proteção contra corrosão
E54: Polipropileno (PP) | F54: Boa resistência mecânica e à abrasão | G54: Boa para uso moderado, resistente à umidade e químicos leves | H54: ~0,9 g/cm³ | I54: Excelente | J54: Alta no Brasil | K54: Baixo | L54: Ótima para injeção e termoformagem | M54: Compartimentos internos, divisórias
E55: Polietileno de Alta Densidade (PEAD) | F55: Alta tenacidade e boa absorção de impacto | G55: Alta, incluindo intempéries e abrasão | H55: ~0,95 g/cm³ | I55: Muito boa | J55: Ampla | K55: Baixo a moderado | L55: Boa para extrusão, moldagem por sopro e injeção | M55: Áreas que exigem mais resistência ao impacto
E56: ABS (Acrilonitrila Butadieno Estireno) | F56: Excelente resistência ao impacto | G56: Boa para aplicações industriais | H56: ~1,04 g/cm³ | I56: Boa (embora inferior ao PP/PEAD) | J56: Boa | K56: Moderado | L56: Excelente para moldes com acabamento estético | M56: Itens com foco visual/ergonômico (ex: tampas, controles)
E57: EPDM (Etileno-Propileno-Dieno) | F57: Boa para cargas moderadas e boa aderência | G57: Excelente: resistente a UV, ozônio e intempéries | H57: – | I57: Alta | J57: Alta | K57: Moderado | L57: Boa para extrusão e moldagem por compressão | M57: Pegadores, bases antiderrapantes, proteção externa
E58: Poliuretano (PU) | F58: Suporta cargas pesadas, alta elasticidade | G58: Muito alta, excelente para abrasão contínua | H58: – | I58: Alta | J58: Boa | K58: Alto | L58: Boa, requer controle de processo | M58: Áreas críticas com exigência de impacto e resistência ao desgaste
E59: Papelão ondulado reciclado | F59: Boa para transporte e empilhamento | G59: Boa | H59: – | I59: Excelente | J59: Alta | K59: Muito baixo | L59: Fácil corte e impressão | M59: Embalagem para envio e armazenagem logística

Sheet 9. PUGH
B2: PESO DO QFD | C2: REQUISITOS DO CLIENTE | D2: ESTRUTURA FUNCIONAL 1 | E2: ESTRUTURA FUNCIONAL 2 (Referência) | F2: ESTRUTURA FUNCIONAL 3
B3: ='7. QFD Final'!D37 -> 5 | C3: ='7. QFD Final'!B37 -> Ter capacidade para suportar as principais ferramentas | D3: 0 | E3: 0 | F3: 1
B4: ='7. QFD Final'!D38 -> 5 | C4: ='7. QFD Final'!B38 -> Ter compartimentos | D4: -1 | E4: 0 | F4: 1
B5: ='7. QFD Final'!D39 -> 5 | C5: ='7. QFD Final'!B39 -> Ser de fácil movimentação | D5: 0 | E5: 0 | F5: 1
B6: ='7. QFD Final'!D40 -> 4 | C6: ='7. QFD Final'!B40 -> Ser durável | D6: 0 | E6: 0 | F6: 0
B7: ='7. QFD Final'!D41 -> 4 | C7: ='7. QFD Final'!B41 -> Ser compacto | D7: 1 | E7: 0 | F7: 1
B8: ='7. QFD Final'!D42 -> 3 | C8: ='7. QFD Final'!B42 -> Ter manutenção simples | D8: 0 | E8: 0 | F8: 2
B9: ='7. QFD Final'!D43 -> 3 | C9: ='7. QFD Final'!B43 -> Ter bom custo benefício | D9: 0 | E9: 0 | F9: -1
B10: ='7. QFD Final'!D44 -> 3 | C10: ='7. QFD Final'!B44 -> Ter fácil desmontagem | D10: -1 | E10: 0 | F10: 2
B11: ='7. QFD Final'!D45 -> 3 | C11: ='7. QFD Final'!B45 -> Ter montagem rápida | D11: 1 | E11: 0 | F11: 1
B12: ='7. QFD Final'!D46 -> 2 | C12: ='7. QFD Final'!B46 -> Ter aparência robusta | D12: 0 | E12: 0 | F12: 0
B13: ='7. QFD Final'!D47 -> 2 | C13: ='7. QFD Final'!B47 -> Ter montagem em poucas etapas | D13: 0 | E13: 0 | F13: -1
B14: ='7. QFD Final'!D48 -> 2 | C14: ='7. QFD Final'!B48 -> Ter matérias-primas acessíveis | D14: 0 | E14: 0 | F14: 0
... B16: ='7. QFD Final'!D50 -> 1 | C16: ='7. QFD Final'!B50 -> Ter embalagem simples | D16: 0 | E16: 0 | F16: 0
D17: =SUMPRODUCT(D3:D16,$B$3:$B$16) -> -1 | E17: =SUMPRODUCT(E3:E16,$B$3:$B$16) -> 0 | F17: =SUMPRODUCT(F3:F16,$B$3:$B$16) -> 29

Sheet 9.1 PUGH da Concepção
B2: PESO DO QFD | C2: REQUISITOS DO CLIENTE | D2: CONCEPÇÃO 1 (referência) | E2: CONCEPÇÃO 2 | F2: CONCEPÇÃO 3
B3: ='7. QFD Final'!D37 -> 5 | C3: ='7. QFD Final'!B37 -> Ter capacidade para suportar as principais ferramentas | D3: 0 | E3: 1 | F3: 1
B4: ='7. QFD Final'!D38 -> 5 | C4: ='7. QFD Final'!B38 -> Ter compartimentos | D4: 0 | E4: 2 | F4: 2
B5: ='7. QFD Final'!D39 -> 5 | C5: ='7. QFD Final'!B39 -> Ser de fácil movimentação | D5: 0 | E5: 1 | F5: 2
B6: ='7. QFD Final'!D40 -> 4 | C6: ='7. QFD Final'!B40 -> Ser durável | D6: 0 | E6: 1 | F6: 1
B7: ='7. QFD Final'!D41 -> 4 | C7: ='7. QFD Final'!B41 -> Ser compacto | D7: 0 | E7: -1 | F7: -1
B8: ='7. QFD Final'!D42 -> 3 | C8: ='7. QFD Final'!B42 -> Ter manutenção simples | D8: 0 | E8: 0 | F8: -1
B9: ='7. QFD Final'!D43 -> 3 | C9: ='7. QFD Final'!B43 -> Ter bom custo benefício | D9: 0 | E9: -2 | F9: 1
B10: ='7. QFD Final'!D44 -> 3 | C10: ='7. QFD Final'!B44 -> Ter fácil desmontagem | D10: 0 | E10: 1 | F10: 1
B11: ='7. QFD Final'!D45 -> 3 | C11: ='7. QFD Final'!B45 -> Ter montagem rápida | D11: 0 | E11: -1 | F11: 1
B12: ='7. QFD Final'!D46 -> 2 | C12: ='7. QFD Final'!B46 -> Ter aparência robusta | D12: 0 | E12: 2 | F12: 2
B13: ='7. QFD Final'!D47 -> 2 | C13: ='7. QFD Final'!B47 -> Ter montagem em poucas etapas | D13: 0 | E13: -1 | F13: -1
B14: ='7. QFD Final'!D48 -> 2 | C14: ='7. QFD Final'!B48 -> Ter matérias-primas acessíveis | D14: 0 | E14: 0 | F14: 0
... B16: ='7. QFD Final'!D50 -> 1 | C16: ='7. QFD Final'!B50 -> Ter embalagem simples | D16: 0 | E16: 0 | F16: 0
D17: =SUMPRODUCT(D3:D16,$B$3:$B$16) -> 0 | E17: =SUMPRODUCT(E3:E16,$B$3:$B$16) -> 15 | F17: =SUMPRODUCT(F3:F16,$B$3:$B$16) -> 32

Sheet 10. Matriz Morfológica 1
B1: Função Parciais | C1: Função Elementares | D1: Princípios de Solução
D2: Concepção 1 | E2: Concepção 2 | F2: Concepção 3 | G2: Concepção 4
B3: Organizar ferramentas | C3: 1. Indicar posições
C4: 2. Travar Ferramentas
C5: 3. Segurar ferramentas
C6: 4. Garantir estabilidade
B7: Bloquear acesso | C7: 5. Travar aberturas
C8: 6. Liberar aberturas
B9: Bloquear movimentação | C9: 7. Travar movimentação
C10: 8. Liberar movimentação
C11: 9. Adequar ao espaço
B12: Movimentar ferramentas | C12: 10. Deslocar módulos
C13: 11. Deslocar móvel
C14: 12. Facilitar locomoção
B15: Movimentar módulos | C15: 13. Destacar módulos
C16: 14. Travar módulos
C17: 15. Juntar módulos
C18: 16. Destravar módulos
C26: Função Elementar | D26: Solução Física 1 | E26: Solução Física 2 | F26: Solução Física 3
C27: Indicar posições | D27: Marcação em baixo relevo nas posições | E27: Cores diferenciadas por posição
C28: Travar ferramentas | D28: Suporte interno com clipe de pressão | E28: Cintas elásticas com fixação por gancho | F28: Slot com aba de retenção
C29: Segurar ferramentas | D29: Espumas recortadas para encaixe sob medida | E29: Base imantada para pequenas peças metálicas | F29: Prendedores com aba dobrável
C30: Garantir estabilidade | D30: Base alargada com cantos emborrachados | E30: Pinos de acoplamento com trava mecânica | F30: Textura antiderrapante na base inferior
C31: Travar aberturas | D31: Fecho tipo maleta com clipe de segurança | E31: Fecho por aba plástica com pino interno | F31: Trava com botão deslizante central
C32: Liberar aberturas | D32: Trilho deslizante com batente final | E32: Alça de abertura com liberação por clique | F32: Aba dobrável com apoio de dedo
C33: Travar movimentação | D33: Clipe de pressão com trava | E33: Encaixe com dente e contra-dente lateral | F33: Trava de apoio inferior com pressão lateral
C34: Liberar movimentação | D34: Gatilho de liberação com mola | E34: Botão de destrave lateral | F34: Rotação de trava para destravar módulos
C35: Adequar ao espaço | D35: Paredes rebatíveis dos módulos | E35: Separadores móveis internos
C36: Deslocar módulos | D36: Trilho de encaixe com roldanas pequenas | E36: Rodas pequenas embutidas nas laterais | F36: Deslizamento por calha embutida
C37: Deslocar móvel | D37: Rodízios com trava para movimentação total | E37: Estrutura inferior com rolamento | F37: Pés retráteis com esferas rotativas
C38: Facilitar locomoção | D38: Alça retrátil tipo mala | E38: Rodas de borracha para piso irregular | F38: Correia lateral para transporte em escada
C39: Destacar módulos | D39: Trava por botão de liberação frontal | E39: Sistema de travamento com pino retrátil | F39: Clipe removível entre os módulos
C40: Travar módulos | D40: Fecho em alça com encaixe mecânico | E40: Trilho com trava de curso | F40: Encaixe macho-fêmea com trava vertical
C41: Juntar módulos | D41: Sistema de clique vertical com guia de encaixe | E41: Conexão por encaixe em trilho deslizante | F41: Trilho inferior com batente de alinhamento
C42: Destravar módulos | D42: Destravador lateral com curso limitado | E42: Alavanca retrátil para soltar encaixe | F42: Trilho com guia de liberação

Sheet 10. Matriz Morfológica 2
B1: Função Parciais | C1: Função Elementares | D1: Princípios de Solução
D2: Concepção 1 | E2: Concepção 2 | F2: Concepção 3 | G2: Concepção 4
B3: Organizar ferramentas | C3: 1. Segurar ferramentas
C4: 2. Garantir estabilidade
B5: Bloquear acesso | C5: 3. Travar aberturas
C6: 4. Liberar aberturas
B7: Bloquear movimentação | C7: 5. Travar movimentação
C8: 6. Liberar movimentação
C9: 7. Adequar ao espaço
B10: Movimentar ferramentas | C10: 8. Deslocar módulos
C11: 9. Deslocar móvel
C12: 1. Facilitar locomoção
B13: Movimentar módulos | C13: 12. Destacar módulos
C14: 12. Travar módulos
C15: 13. Juntar módulos
C16: 14. Destravar módulos

Sheet MIM
B3: Matriz Indicadora de Módulos | D3: Bloquear acesso | E3: Organizar ferramentas | F3: Bloquear movimentação | G3: Movimentar ferramentas | H3: Movimentar módulos
D6: Funções
B7: Desenvolvimento de produtos | C7: Multiplicativo (“Carry-Over”) | F7: 𒊹 | H7: 𒊹
C8: Evolução tecnológica | H8: Ｏ
C9: Planejamento de alteração de projeto
B10: Variação | C10: Especificação técnica | E10: 𒊹 | G10: 🌓
C11: Estilo
B12: Fabricação | C12: Unidade comum | D12: 𒊹 | F12: 🌓 | H12: 🌓
C13: Processo e organização | E13: 𒊹
B14: Qualidade | C14: Testes em separado | D14: 🌓 | E14: 🌓 | F14: 🌓 | G14: 🌓 | H14: 🌓
B15: Aquisição | C15: Compra de produtos prontos | D15: 𒊹 | H15: 𒊹
B16: Após estar no mercado | C16: Manutenção e Mantenabilidade | D16: 𒊹 | H16: 𒊹
C17: Atualização | E17: 🌓 | H17: 🌓
C18: Reciclagem | F18: Ｏ
B19: Soma | D19: 18 | E19: 16 | F19: 12 | G19: 6 | H19: 25
B20: Classificação | D20: 2 | E20: 3 | F20: 4 | G20: 5 | H20: 1
C23: 3 módulos
C25: Fraca Relação (1 ponto) | D25: Ｏ
C26: Média Relação (3 pontos) | D26: 🌓
C27: Forte Relação (5 pontos) | D27: 𒊹

Sheet TRIZ
A1: Ideias de materiais:
A2: Placa de ACM
A3: Tampa de acrílico
A4: travas de metal para travar módulos
A5: definir tamanhos ( pensar nos tamanhos das ferramentas, pra ter uma ideia)
I80: Escolhido

Sheet Materiais
A1: Ideias de materiais:
A2: Placa de ACM
A3: Tampa de acrílico
A4: travas de metal para travar módulos
A5: definir tamanhos ( pensar nos tamanhos das ferramentas, pra ter uma ideia)

Sheet Pendências
A1: Terminar matriz morfológica | C1: Posterior | D1: Apresentação
A2: - Matriz indicadora de Módulos | C2: Terminar matriz morfológica | D2: - análise técnica (seleção de materiais)
A3: - TRIZ | C3: - atualizar o relatório com os feeds da professora | D3: - Análise técnica do projeto do produto;
A4: - atualizar o relatório com os feeds da professora | D4: - Análise de viabilidade econômica do projeto.
A5: - 3 arquiteturas do produto | D5: - CANVAS PRELIMINAR + Budget do projeto (Investimento)
A6: - análise técnica (seleção de materiais) | D6: - TRL
A7: - Análise técnica do projeto do produto;
A8: - Análise de viabilidade econômica do projeto.
A9: - CANVAS PRELIMINAR + Budget do projeto (Investimento)
A10: - TRL
B15: PROBLEMÁTICA | C15: REQUISITOS DO CLIENTE | D15: CUSTO META | E15: NOSSA SOLUÇÃO | F15: TRL | G15: CONCORRENTES
