Workbook

Sheet Cronograma
A1: CRONOGRAMA PSP6 · ENGENHARIA DE PRODUTO
G3: Concluído | K3: Em andamento | O3: Previsto | S3: ◆ Entrega/marco
G4: Feriado | K4: Prova | O4: Evento | S4: 2ª avaliação
A6: 1 · GANTT DAS ATIVIDADES DO PROJETO
A7: Fase | B7: Atividade | C7: Início | D7: Fim | E7: Situação | F7: Agosto | J7: Setembro | N7: Outubro | R7: Novembro | W7: Dezembro
F8: 10/08 | G8: 17/08 | H8: 24/08 | I8: 31/08 | J8: 07/09 | K8: 14/09 | L8: 21/09 | M8: 28/09 | N8: 05/10 | O8: 12/10 | P8: 19/10 | Q8: 26/10 | R8: 02/11 | S8: 09/11 | T8: 16/11 | U8: 23/11 | V8: 30/11 | W8: 07/12 | X8: 09/12
A9: Pré-desenvolvimento | B9: Ambientação: palestras, vídeos e formação do grupo | C9: 46244 | D9: 46244 | E9: Concluído
B10: Local/atividade, usuários e clientes (Lauff et al., p. 31) | C10: 46251 | D10: 46251 | E10: Concluído
B11: Levantamento de informações: entrevistas, visita técnica e pesquisa bibliográfica (Lauff et al., p. 87) | C11: 46251 | D11: 46265 | E11: Concluído
B12: 1ª Entrega de PSP6 — apresentação da sustentação do problema | C12: 46265 | D12: 46265 | E12: Concluído | I12: ◆
A13: Projeto informacional | B13: Ciclo de vida, necessidades dos clientes e matriz de atributos | C13: 46265 | D13: 46272 | E13: Concluído
B14: Requisitos dos clientes e requisitos valorizados (Kano, Mudge e Pareto) | C14: 46272 | D14: 46279 | E14: Concluído
B15: Benchmarking, QFD e especificações-meta | C15: 46279 | D15: 46286 | E15: Concluído
B16: Consolidação do relatório em normas ABNT | C16: 46279 | D16: 46293 | E16: Concluído
B17: 2ª Entrega de PSP6 — relatório consolidado | C17: 46293 | D17: 46293 | E17: Concluído | M17: ◆
A18: Avaliações | B18: Primeira prova de produto | C18: 46300 | D18: 46300 | E18: Concluído | N18: ◆
A19: Projeto conceitual | B19: Modelagem funcional: função global, FAST e funções parciais (3 modelos) | C19: 46300 | D19: 46321 | E19: Modelagem revisada; 23 vínculos e 17 funções
B20: Seleção da modelagem pela matriz de Pugh | C20: 46321 | D20: 46321 | E20: Comparação funcional feita; M1 priorizada
B21: Princípios de solução: matriz morfológica e TRIZ | C21: 46321 | D21: 46335 | E21: Em andamento
B22: Módulos do produto: MIM e arquitetura modular | C22: 46335 | D22: 46342 | E22: MIM herdada; reavaliar sob M1
B23: Concepções e matriz de Pugh das concepções | C23: 46342 | D23: 46349 | E23: Previsto
B24: Otimização: lista de materiais, viabilidade técnica e análise de valor | C24: 46349 | D24: 46356 | E24: Previsto
A25: Fechamento | B25: Preparação da apresentação final | C25: 46349 | D25: 46358 | E25: Previsto
B26: Apresentação final de PSP6 | C26: 46358 | D26: 46358 | E26: Previsto | V26: ◆
A27: Avaliações | B27: Segunda avaliação | C27: 46363 | D27: 46363 | E27: Previsto | W27: ◆
B28: Revisão de nota | C28: 46365 | D28: 46365 | E28: Previsto
A30: 2 · CRONOGRAMA OFICIAL DA DISCIPLINA
A31: Planejamento | B31: Entregas | C31: Data | D31: Observação | F31: Referências / Eng. Produto
A32: Aula 01 | C32: 46244 | F32: Palestras, vídeos
A33: Aula 02 | B33: Local/Atividade — Usuários/Clientes | C33: 46251 | F33: Lauff et al., Design Innovation Handbook (responder as perguntas da página 31)
A34: Aula 03 | B34: Levantamento das informações (sustentação do problema) | C34: 46258 | F34: Entrevistas, visitas técnicas, levantamento bibliográfico. Lauff et al., Design Innovation Handbook (responder as perguntas da página 87)
A35: Aula 04 | B35: Só apresentação | C35: 46265 | D35: 1ª Entrega de PSP6
A36: — | C36: 46272 | D36: Feriado
A37: Aula 05 | B37: Requisitos dos clientes e requisitos valorizados | C37: 46279 | F37: Aulas 6 e 7
A38: Aula 06 | B38: Especificações-meta | C38: 46286 | F38: Aulas 8 e 9 (QFD)
A39: Aula 07 | B39: Entrega do relatório consolidado | C39: 46293 | D39: 2ª Entrega de PSP6 | F39: Normas ABNT
A40: — | C40: 46300 | D40: Primeira prova de produto
A41: — | C41: 46307 | D41: Feriado
A42: — | C42: 46314 | D42: ENEGEP 2026
A43: Aula 08 | B43: Modelagem funcional (3 modelos) e seleção da modelagem | C43: 46321 | F43: Aulas 11, 12 e 13 (síntese funcional)
...

Sheet Revisão
A1: Revisão do escopo do produto
A2: Síntese do recorte | D2: Tipo de projeto | E2: Plataforma
A3: Pergunta | B3: Resposta sustentada | D3: Estratégia de produção | E3: ATO
A4: Onde ocorre o elo crítico? | B4: Hipótese de foco: transporte do distribuidor à obra, descarga e manuseios. Relatos iniciais não medem a participação causal de cada etapa. | D4: Arquitetura | E4: Modular (premissa em avaliação)
A5: Quem absorve diretamente? | B5: No relato do distribuidor, reposição e nova logística são absorvidas por ele. Confirmar em registros; não generalizar a todos os distribuidores.
A6: Por que o problema persiste? | B6: Existe tensão entre maior proteção e preço competitivo. As alternativas de alta proteção podem elevar custo e volume logístico.
A8: Cadeia observada
A9: Etapa | B9: Fabricação/distribuição | C9: Transporte externo | D9: Recebimento/abertura | E9: Movimentação interna | F9: Instalação | G9: Situação atual
A10: Papel | B10: Preparar e expedir | C10: Levar até a obra | D10: Descarregar e conferir | E10: Levar até o ponto de uso | F10: Instalar a louça | G10: Mapeada
A11: Evidência disponível | B11: Escala setorial | C11: Distribuidor associa avarias ao trecho | D11: Peças podem chegar trincadas | E11: Quedas no transporte manual sem acesso para carrinho | F11: A avaria pode se tornar visível nesta etapa | G11: Qualitativa
A12: Risco | B12: Dano latente | C12: Impacto/vibração/manuseio | D12: Fragmentos na abertura | E12: Queda e esforço manual | F12: Retrabalho e risco ao trabalhador | G12: A validar
A13: Decisão futura | B13: Embalagem e unitização | C13: Proteção e movimentação | D13: Conferência segura | E13: Acesso e auxílio de transporte | F13: Critério de aceitação | G13: Projeto informacional
A15: Enunciados de projeto
A16: Problema definido | B16: A quebra no transporte entre distribuidor e obra pode permanecer oculta até o recebimento ou a instalação. O evento gera reposição, nova entrega, atraso, desperdício e exposição do trabalhador a peças avariadas ou fragmentos cortantes.
A17: Opportunity statement | B17: Como podemos reduzir as avarias de louças sanitárias no transporte entre o distribuidor e a obra, diminuindo custos de reposição, atrasos e riscos aos trabalhadores, sem inviabilizar comercialmente o produto ou a operação?
B20: 14/10/2026 — revisão do projeto conceitual
B21: Corrigidos: evidência versus estimativa na V0; fronteiras e inspeção; histórico Pugh (12/0/40) e revisão pendente; conceitos TRIZ; combinações morfológicas; linha de base por RP e custo completo. MIM, módulos e concepções preparados como propostas, sem resultados de ensaio.
A24: Feedback 2 — revisão do escopo antes da definição do ciclo de vida | B24: Feedback 2 — revisão do escopo antes da definição do ciclo de vida | C24: Feedback 2 — revisão do escopo antes da definição do ciclo de vida | D24: Feedback 2 — revisão do escopo antes da definição do ciclo de vida | E24: Feedback 2 — revisão do escopo antes da definição do ciclo de vida | F24: Feedback 2 — revisão do escopo antes da definição do ciclo de vida | G24: Feedback 2 — revisão do escopo antes da definição do ciclo de vida
A25: Atividade | B25: Objetivo | C25: Entrada | D25: Entrega | E25: Aplicação | F25: Natureza | G25: Situação
A26: Revisar escopo | B26: Reavaliar problema, atores, fronteiras, restrições e premissas | C26: Pré-desenvolvimento e devolutiva | D26: Recorte revisto e limites | E26: Proteção e movimentação distribuidor–obra; retorno | F26: Decisão de planejamento | G26: Revisão documental aplicada
A27: Definir ciclo de vida | B27: Descrever a trajetória da solução dentro do escopo revisto | C27: Recorte de projeto revisto | D27: Ciclo macro, 13 fases operacionais, atores e estados | E27: Obtenção, uso, manutenção, retorno e fim de vida | F27: Modelo para levantar necessidades | G27: Descrito no relatório e na Lista de Necessidades
A29: Alcance: uma obra residencial observada e duas entrevistas (operário e distribuidor). A solução é uma hipótese para esse contexto; ampliar campo, mix e condições de uso antes de afirmar abrangência. A taxa de avaria e o custo real ainda não foram medidos. | B29: Alcance: uma obra residencial observada e duas entrevistas (operário e distribuidor). A solução é uma hipótese para esse contexto; ampliar campo, mix e condições de uso antes de afirmar abrangência. A taxa de avaria e o custo real ainda não foram medidos. | C29: Alcance: uma obra residencial observada e duas entrevistas (operário e distribuidor). A solução é uma hipótese para esse contexto; ampliar campo, mix e condições de uso antes de afirmar abrangência. A taxa de avaria e o custo real ainda não foram medidos. | D29: Alcance: uma obra residencial observada e duas entrevistas (operário e distribuidor). A solução é uma hipótese para esse contexto; ampliar campo, mix e condições de uso antes de afirmar abrangência. A taxa de avaria e o custo real ainda não foram medidos. | E29: Alcance: uma obra residencial observada e duas entrevistas (operário e distribuidor). A solução é uma hipótese para esse contexto; ampliar campo, mix e condições de uso antes de afirmar abrangência. A taxa de avaria e o custo real ainda não foram medidos. | F29: Alcance: uma obra residencial observada e duas entrevistas (operário e distribuidor). A solução é uma hipótese para esse contexto; ampliar campo, mix e condições de uso antes de afirmar abrangência. A taxa de avaria e o custo real ainda não foram medidos. | G29: Alcance: uma obra residencial observada e duas entrevistas (operário e distribuidor). A solução é uma hipótese para esse contexto; ampliar campo, mix e condições de uso antes de afirmar abrangência. A taxa de avaria e o custo real ainda não foram medidos.
A31: Lições: detectar dano não prova sua origem; louça é o objeto protegido; a solução física é o produto do projeto; retorno exige manutenção e custo. Comentários da banca: fechar essas lições, separar escopo/ciclo, explicar Kano–Mudge e validar metas estimadas. | B31: Lições: detectar dano não prova sua origem; louça é o objeto protegido; a solução física é o produto do projeto; retorno exige manutenção e custo. Comentários da banca: fechar essas lições, separar escopo/ciclo, explicar Kano–Mudge e validar metas estimadas. | C31: Lições: detectar dano não prova sua origem; louça é o objeto protegido; a solução física é o produto do projeto; retorno exige manutenção e custo. Comentários da banca: fechar essas lições, separar escopo/ciclo, explicar Kano–Mudge e validar metas estimadas. | D31: Lições: detectar dano não prova sua origem; louça é o objeto protegido; a solução física é o produto do projeto; retorno exige manutenção e custo. Comentários da banca: fechar essas lições, separar escopo/ciclo, explicar Kano–Mudge e validar metas estimadas. | E31: Lições: detectar dano não prova sua origem; louça é o objeto protegido; a solução física é o produto do projeto; retorno exige manutenção e custo. Comentários da banca: fechar essas lições, separar escopo/ciclo, explicar Kano–Mudge e validar metas estimadas. | F31: Lições: detectar dano não prova sua origem; louça é o objeto protegido; a solução física é o produto do projeto; retorno exige manutenção e custo. Comentários da banca: fechar essas lições, separar escopo/ciclo, explicar Kano–Mudge e validar metas estimadas. | G31: Lições: detectar dano não prova sua origem; louça é o objeto protegido; a solução física é o produto do projeto; retorno exige manutenção e custo. Comentários da banca: fechar essas lições, separar escopo/ciclo, explicar Kano–Mudge e validar metas estimadas.
A33: 14/10/2026 — Feedback 2 registrado em logs-ajustes. Correções documentais aplicadas; ampliação do campo e ensaios pendentes. Sem alteração automática das categorias Kano, dos pesos Mudge/QFD ou da seleção pendente de M3. | B33: 14/10/2026 — Feedback 2 registrado em logs-ajustes. Correções documentais aplicadas; ampliação do campo e ensaios pendentes. Sem alteração automática das categorias Kano, dos pesos Mudge/QFD ou da seleção pendente de M3. | C33: 14/10/2026 — Feedback 2 registrado em logs-ajustes. Correções documentais aplicadas; ampliação do campo e ensaios pendentes. Sem alteração automática das categorias Kano, dos pesos Mudge/QFD ou da seleção pendente de M3. | D33: 14/10/2026 — Feedback 2 registrado em logs-ajustes. Correções documentais aplicadas; ampliação do campo e ensaios pendentes. Sem alteração automática das categorias Kano, dos pesos Mudge/QFD ou da seleção pendente de M3. | E33: 14/10/2026 — Feedback 2 registrado em logs-ajustes. Correções documentais aplicadas; ampliação do campo e ensaios pendentes. Sem alteração automática das categorias Kano, dos pesos Mudge/QFD ou da seleção pendente de M3. | F33: 14/10/2026 — Feedback 2 registrado em logs-ajustes. Correções documentais aplicadas; ampliação do campo e ensaios pendentes. Sem alteração automática das categorias Kano, dos pesos Mudge/QFD ou da seleção pendente de M3. | G33: 14/10/2026 — Feedback 2 registrado em logs-ajustes. Correções documentais aplicadas; ampliação do campo e ensaios pendentes. Sem alteração automática das categorias Kano, dos pesos Mudge/QFD ou da seleção pendente de M3.
B36: 14/10/2026 — MIM conceitual pontuada para a referência C1 | C36: 14/10/2026 — MIM conceitual pontuada para a referência C1 | D36: 14/10/2026 — MIM conceitual pontuada para a referência C1 | E36: 14/10/2026 — MIM conceitual pontuada para a referência C1 | F36: 14/10/2026 — MIM conceitual pontuada para a referência C1 | G36: 14/10/2026 — MIM conceitual pontuada para a referência C1
B37: Registrados 156 julgamentos (12 direcionadores × 13 portadores), escala 0/1/3/5 da base, somas/posições, OP-01 fora por padrão, justificativas e quatro núcleos propostos. Interfaces e troca de MD2/MD3/MD4 ainda precisam de dimensionamento e ensaio; C1 não foi selecionada. | C37: Registrados 156 julgamentos (12 direcionadores × 13 portadores), escala 0/1/3/5 da base, somas/posições, OP-01 fora por padrão, justificativas e quatro núcleos propostos. Interfaces e troca de MD2/MD3/MD4 ainda precisam de dimensionamento e ensaio; C1 não foi selecionada. | D37: Registrados 156 julgamentos (12 direcionadores × 13 portadores), escala 0/1/3/5 da base, somas/posições, OP-01 fora por padrão, justificativas e quatro núcleos propostos. Interfaces e troca de MD2/MD3/MD4 ainda precisam de dimensionamento e ensaio; C1 não foi selecionada. | E37: Registrados 156 julgamentos (12 direcionadores × 13 portadores), escala 0/1/3/5 da base, somas/posições, OP-01 fora por padrão, justificativas e quatro núcleos propostos. Interfaces e troca de MD2/MD3/MD4 ainda precisam de dimensionamento e ensaio; C1 não foi selecionada. | F37: Registrados 156 julgamentos (12 direcionadores × 13 portadores), escala 0/1/3/5 da base, somas/posições, OP-01 fora por padrão, justificativas e quatro núcleos propostos. Interfaces e troca de MD2/MD3/MD4 ainda precisam de dimensionamento e ensaio; C1 não foi selecionada. | G37: Registrados 156 julgamentos (12 direcionadores × 13 portadores), escala 0/1/3/5 da base, somas/posições, OP-01 fora por padrão, justificativas e quatro núcleos propostos. Interfaces e troca de MD2/MD3/MD4 ainda precisam de dimensionamento e ensaio; C1 não foi selecionada.
B40: 15/10/2026 — separação entre requisitos, funções, atributos e restrições | C40: 15/10/2026 — separação entre requisitos, funções, atributos e restrições | D40: 15/10/2026 — separação entre requisitos, funções, atributos e restrições | E40: 15/10/2026 — separação entre requisitos, funções, atributos e restrições | F40: 15/10/2026 — separação entre requisitos, funções, atributos e restrições | G40: 15/10/2026 — separação entre requisitos, funções, atributos e restrições
B41: Mantidos 23 RP e 23 metas. V01–V23 registram vínculos; catálogo reúne 17 funções sem duplicar uniformidade/vida nem converter custo em efeito físico. FAST, estruturas, morfológica, MIM e relatório alinhados. Julgamentos da MIM e seleções pendentes preservados. | C41: Mantidos 23 RP e 23 metas. V01–V23 registram vínculos; catálogo reúne 17 funções sem duplicar uniformidade/vida nem converter custo em efeito físico. FAST, estruturas, morfológica, MIM e relatório alinhados. Julgamentos da MIM e seleções pendentes preservados. | D41: Mantidos 23 RP e 23 metas. V01–V23 registram vínculos; catálogo reúne 17 funções sem duplicar uniformidade/vida nem converter custo em efeito físico. FAST, estruturas, morfológica, MIM e relatório alinhados. Julgamentos da MIM e seleções pendentes preservados. | E41: Mantidos 23 RP e 23 metas. V01–V23 registram vínculos; catálogo reúne 17 funções sem duplicar uniformidade/vida nem converter custo em efeito físico. FAST, estruturas, morfológica, MIM e relatório alinhados. Julgamentos da MIM e seleções pendentes preservados. | F41: Mantidos 23 RP e 23 metas. V01–V23 registram vínculos; catálogo reúne 17 funções sem duplicar uniformidade/vida nem converter custo em efeito físico. FAST, estruturas, morfológica, MIM e relatório alinhados. Julgamentos da MIM e seleções pendentes preservados. | G41: Mantidos 23 RP e 23 metas. V01–V23 registram vínculos; catálogo reúne 17 funções sem duplicar uniformidade/vida nem converter custo em efeito físico. FAST, estruturas, morfológica, MIM e relatório alinhados. Julgamentos da MIM e seleções pendentes preservados.
B44: 15/10/2026 — primeira Pugh funcional e escolha da fronteira M1 | C44: 15/10/2026 — primeira Pugh funcional e escolha da fronteira M1 | D44: 15/10/2026 — primeira Pugh funcional e escolha da fronteira M1 | E44: 15/10/2026 — primeira Pugh funcional e escolha da fronteira M1 | F44: 15/10/2026 — primeira Pugh funcional e escolha da fronteira M1 | G44: 15/10/2026 — primeira Pugh funcional e escolha da fronteira M1
B45: Pugh qualitativo: empate 0/0/0, com vantagem potencial de acesso e operação extra de preparo em M1. A equipe priorizou M1. Morfológica e C1/C2/C3 ajustadas para peça descoberta; escores da MIM preservados como histórico e reavaliação reaberta. Metas e segunda seleção continuam aplicáveis. | C45: Pugh qualitativo: empate 0/0/0, com vantagem potencial de acesso e operação extra de preparo em M1. A equipe priorizou M1. Morfológica e C1/C2/C3 ajustadas para peça descoberta; escores da MIM preservados como histórico e reavaliação reaberta. Metas e segunda seleção continuam aplicáveis. | D45: Pugh qualitativo: empate 0/0/0, com vantagem potencial de acesso e operação extra de preparo em M1. A equipe priorizou M1. Morfológica e C1/C2/C3 ajustadas para peça descoberta; escores da MIM preservados como histórico e reavaliação reaberta. Metas e segunda seleção continuam aplicáveis. | E45: Pugh qualitativo: empate 0/0/0, com vantagem potencial de acesso e operação extra de preparo em M1. A equipe priorizou M1. Morfológica e C1/C2/C3 ajustadas para peça descoberta; escores da MIM preservados como histórico e reavaliação reaberta. Metas e segunda seleção continuam aplicáveis. | F45: Pugh qualitativo: empate 0/0/0, com vantagem potencial de acesso e operação extra de preparo em M1. A equipe priorizou M1. Morfológica e C1/C2/C3 ajustadas para peça descoberta; escores da MIM preservados como histórico e reavaliação reaberta. Metas e segunda seleção continuam aplicáveis. | G45: Pugh qualitativo: empate 0/0/0, com vantagem potencial de acesso e operação extra de preparo em M1. A equipe priorizou M1. Morfológica e C1/C2/C3 ajustadas para peça descoberta; escores da MIM preservados como histórico e reavaliação reaberta. Metas e segunda seleção continuam aplicáveis.
B47: 21/10/2026 — MF-A/MF-B/MF-C, FAST e primeira Pugh revisadas
B48: 23 RP e 17 funções preservados. Nova comparação da organização do amortecimento, com indicação conceitual MF-B e sensibilidade explícita. Imagens mantidas junto aos quadros editáveis. Morfológica, concepções, MIM e arquitetura sinalizam a reavaliação necessária, sem transferir resultados históricos.
B50: 21/10/2026 — primeira Pugh ampliada para os 23 requisitos
B51: Substituída a seleção por dois critérios por análise ampla, com vínculos às 17 funções, equivalências justificadas e AV explícitos. Retirados +1/−1 automáticos de MF-B/MF-C. Resultado em aberto, com dependências posteriores alinhadas; metas, pesos, imagens e MIM numérica preservados.
B53: 21/10/2026 — avaliação conceitual da primeira Pugh com princípios de apoio
B54: Hipóteses H1–H5 registradas. Avaliados mais seis critérios: RP3/RP7/RP13/RP15/RP19/RP20. MF-B tem saldo parcial +2 e MF-C −1, com nove AV cada. A seleção permanece aberta. Preservados requisitos, metas, pesos, funções, figuras e julgamentos numéricos da MIM.
B56: 21/10/2026 — recorte qualitativo de mix e transporte informado pela equipe
B57: Estudar louças médias, incluindo cubas e bacias/vasos, compatíveis com os veículos/métodos de envio. Levantar dimensões, massas, apoios e arranjo de carga por família. Metas, notas e nove AV da Pugh preservados; empilhamento continua a dimensionar.
B59: 21/10/2026 — referências de catálogo e cenário físico preliminar
B60: Definidas faixas de cubas/bacias individuais, carga, envelope, paletização e caso de dois níveis/24 h. RP7/RP8/RP14 revistos; compressão 7,5 kN mantida provisória. QFD,17 funções e notas da Pugh preservados; nove AV por alternativa.
...

Sheet Dados 
A1: 1 | B1: Amortecer impactos do transporte
A2: 2 | B2: Imobilizar a louça
A3: 3 | B3: Permitir conferência sem abrir
A4: 4 | B4: Ser ajustável a diferentes louças
A5: 5 | B5: Ser compatível com o veículo
A6: 6 | B6: Ser de fácil movimentação
A7: 7 | B7: Ter pontos de pega definidos
A8: 8 | B8: Ter retirada segura da louça
A9: 9 | B9: Ser de uso intuitivo
A10: 10 | B10: Ser compacto
A11: 11 | B11: Ser empilhável
A12: 12 | B12: Ter desempenho uniforme
... A23: 23 | B23: Ser estável quando apoiado
B27: Referência preliminar de peças e transporte — revisão de 21/10/2026
B28: Uma peça cerâmica por dispositivo, no fluxo distribuidor–obra. Famílias iniciais: cubas e corpos de bacias/vasos sem caixa acoplada. Kits montados, monoblocos e peças fora dos limites exigem outra configuração e nova avaliação.
B29: Catálogo = dado publicado. Premissa = limite escolhido para desenvolver e comparar as três modelagens. Cálculo = resultado dessas entradas. Nenhuma linha representa ensaio do protótipo. Campos vazios/inválidos bloqueiam os cálculos; controle na linha130.
B31: Modelo / código | C31: Família | D31: A (mm) | E31: B (mm) | F31: H (mm) | G31: Massa (kg) | H31: Fonte | I31: Observação
B32: Celite Basic Q5 1730490027300 | C32: Cuba | D32: 350 | E32: 350 | F32: 135 | H32: S1 | I32: Massa não informada na ficha consultada; pesar.
B33: Celite Design D5 1380850077300 | C33: Cuba | D33: 450 | E33: 400 | F33: 95 | G33: 9.5 | H33: S2 | I33: A/B normalizados a partir de 400 × 450 mm.
B34: Deca Liquid L.13050.LQ.17 | C34: Cuba | D34: 500 | E34: 350 | F34: 140 | G34: 9.746 | H34: S3 | I34: Peso líquido; modelo cerâmico, sem confundir com cuba inox LI.
B35: Celite Like 1643550010300 | C35: Bacia | D35: 610 | E35: 360 | F35: 370 | G35: 18 | H35: S4 | I35: Corpo da bacia; peso declarado como Peso KG.
B36: Celite Elite 1743530010300 | C36: Bacia | D36: 565 | E36: 360 | F36: 400 | G36: 27 | H36: S5 | I36: Caixa, assento e instalação vendidos separadamente.
B37: Deca LK P.23.17 | C37: Bacia | D37: 515 | E37: 355 | F37: 400 | G37: 32.341 | H37: S6 | I37: Peso líquido; AxLxC da fonte = 400 × 355 × 515 mm.
B38: Deca Flex KP.381.BR.17 | C38: Kit montado | D38: 600 | E38: 360 | F38: 760 | G38: 39.449 | H38: S7 | I38: Fora do recorte compacto: a caixa aumenta a altura. Não representa o corpo isolado.
B39: A é o maior lado horizontal e B o lado perpendicular, preservando H e a posição vertical de transporte. Não representam a área de contato. Confirmar apoio admissível, curvatura, áreas frágeis, massa e centro de gravidade por modelo.
B41: Faixa nominal de desenvolvimento — premissa, não cobertura comercial comprovada
B42: Família | C42: A mín. (mm) | D42: A máx. (mm) | E42: B mín. (mm) | F42: B máx. (mm) | G42: H mín. (mm) | H42: H máx. (mm) | I42: Massa máx. (kg) | J42: Natureza
B43: Cubas | C43: 350 | D43: 600 | E43: 300 | F43: 420 | G43: 80 | H43: 200 | I43: 15 | J43: Premissa a verificar
B44: Bacias | C44: 500 | D44: 630 | E44: 340 | F44: 400 | G44: 350 | H44: 420 | I44: 40 | J44: Premissa a verificar
B45: Amostras de catálogo delimitam referências, sem demonstrar representatividade do mix. As extensões até 600/630 mm e os tetos de 15/40 kg são margens de desenvolvimento escolhidas pela equipe; dependem do estoque e do volume vendido.
B46: Aceitar um SKU exige também contato protegido e imobilização sem dano, inspeção da cerâmica, retenção e atendimento ao envelope. Caber na caixa delimitadora é necessário, mas não basta. Peças fora da faixa não entram por suposição.
B48: Entradas para dimensionamento e comparação comum de MF-A, MF-B e MF-C
B49: Reserva dimensional em cada dimensão nominal | E49: 10 | F49: mm | G49: Premissa ±10 mm; Celite informa aproximadamente 10 mm. Para outros fabricantes, confirmar a tolerância aplicável.
B50: Massa máxima da cuba | E50: =I43 -> 15 | F50: kg | G50: Limite de desenvolvimento da família.
B51: Massa máxima da bacia | E51: =I44 -> 40 | F51: kg | G51: Limite de desenvolvimento da família.
B52: Massa cerâmica do caso carregado | E52: 40 | F52: kg | G52: Caso comum conservador; não é limite de levantamento manual.
B53: Orçamento de massa do dispositivo | E53: 8 | F53: kg | G53: Premissa para estrutura, contatos, barreira e interfaces; pesar BOM/protótipo.
B54: Massa máxima do conjunto | E54: =IF(AND(COUNT(E52:E53)=2,MIN(E52:E53)>0),E52+E53,"Pendente") -> 48 | F54: kg | G54: Cerâmica + dispositivo. A interface de carrinho deve ser verificada com esta carga.
B55: Curso mínimo de ajuste no eixo A | E55: 300 | F55: mm | G55: Sem troca de componentes no ajuste. A faixa com reserva vai de 340 a 640 mm.
B56: Curso mínimo de ajuste no eixo B | E56: 150 | F56: mm | G56: Sem troca de componentes no ajuste. A faixa com reserva vai de 290 a 430 mm.
...

Sheet Lista de Necessidades
A1: Etapa do Ciclo de Vida | B1: ID | C1: Necessidade do Cliente | D1: Categoria | E1: Sim ou não | F1: =COUNTIF(E2:E45,"True")
A2: Projeto | B2: 1 | C2: Ter peças modulares | D2: Interno | E2: True
A3: Projeto | B3: 2 | C3: Ter semelhança entre as peças | D3: Interno | E3: True
A4: Projeto | B4: 3 | C4: Ter poucos tipos de componentes | D4: Interno | E4: True
A5: Projeto | B5: 4 | C5: Ser adaptável às variações de louça | D5: Interno | E5: True
A6: Fabricação | B6: 5 | C6: Ter matéria-prima acessível no mercado local | D6: Interno | E6: True
A7: Fabricação | B7: 6 | C7: Ter geometria simples de fabricar | D7: Interno | E7: True
A8: Fabricação | B8: 7 | C8: Ter geometria repetível entre lotes | D8: Interno | E8: True
A9: Armazenagem de peças | B9: 8 | C9: Ter peças identificáveis visualmente | D9: Interno | E9: True
A10: Armazenagem de peças | B10: 9 | C10: Resistir à degradação por umidade no estoque | D10: Interno | E10: True
A11: Armazenagem de peças | B11: 10 | C11: Ter peças empilháveis | D11: Interno | E11: True
A12: Montagem | B12: 11 | C12: Ter encaixes intuitivos | D12: Interno | E12: True
A13: Montagem | B13: 12 | C13: Ter montagem em poucas etapas | D13: Interno | E13: True
... A45: Descarte | B45: 44 | C45: Ter materiais recicláveis | D45: Externo | E45: True

Sheet Matriz de Atributos
B2: CICLO DE VIDA | C2: FUNCIONAMENTO | D2: ERGONOMIA E SEGURANÇA | E2: EFICIÊNCIA OPERACIONAL | F2: DURABILIDADE E ROBUSTEZ | G2: CONFIABILIDADE | H2: ECONÔMICO | I2: MODULARIDADE | J2: SUSTENTABILIDADE E CONFORMIDADE
B3: Projeto | C3: Ser adaptável às variações de louça (4) | I3: Ter peças modulares (1) Ter semelhança entre as peças (2) Ter poucos tipos de componentes (3)
B4: Fabricação | E4: Ter geometria simples de fabricar (6) | G4: Ter dimensões e tolerâncias repetíveis entre lotes (7) | H4: Ter matéria-prima acessível no mercado local (5)
B5: Armazenagem de peças | E5: Ter peças empilháveis (10) | F5: Ser resistente à umidade e à corrosão no estoque (9) | G5: Ter peças identificáveis visualmente (8)
B6: Montagem | C6: Ter indicação visual de montagem correta (14) | D6: Dispensar ferramenta especial para montar (13) | E6: Ter montagem em poucas etapas (12) | I6: Ter encaixes intuitivos (11)
B7: Armazenagem do produto | E7: Ser compacto quando vazio (15) Ser empilhável e estável (16) | F7: Resistir às intempéries de estocagem (17)
B8: Venda | G8: Ter vida útil declarada em número de ciclos (20) | H8: Ter custo por ciclo inferior ao da avaria evitada (18) | I8: Ter configurações padronizadas (19)
B9: Distribuição | C9: Ser compatível com o veículo, a unitização e a amarração (21) | E9: Ocupar pouco espaço no transporte (22) | F9: Proteger o próprio produto até o distribuidor (23)
B10: Uso no distribuidor | C10: Acomodar as variações de louça do distribuidor (26) | D10: Ser de uso intuitivo, sem treinamento formal (24) Ter pontos de pega definidos (25) | G10: Ter indicação visual de fechamento correto (27)
B11: Função | C11: Amortecer impacto e vibração (28) Imobilizar a louça (29) Evitar atrito entre a louça e o produto (30) Permitir conferir a integridade da louça sem abrir (31)
B12: Movimentação na obra | D12: Ter dimensões compatíveis com portas e corredores (32) Ter peso compatível com o transporte por duas pessoas (33) Permitir retirar a louça sem contato com aresta cortante (34) | E12: Ser estável quando apoiado no canteiro (35)
B13: Manutenção | D13: Ser de fácil limpeza (38) | H13: Ter peça de reposição de baixo custo (37) | I13: Ter peças substituíveis individualmente (36)
B14: Retorno | E14: Ser dobrável ou desmontável para o retorno (39) | F14: Suportar ciclos repetidos de uso (40) | J14: Ter identificação para rastreio do retorno (41)
B15: Descarte | J15: Ter materiais identificados (42) Ser de fácil desmontagem (43) Ter materiais recicláveis (44)
B16: Etapa do Ciclo de Vida | C16: ID | D16: Necessidade do Cliente | E16: Categoria | F16: Sim ou não | G16: =COUNTIF(F17:F60,"True")
B17: Projeto | C17: 1 | D17: Ter peças modulares | E17: Interno | F17: True
B18: Projeto | C18: 2 | D18: Ter semelhança entre as peças | E18: Interno | F18: True
B19: Projeto | C19: 3 | D19: Ter poucos tipos de componentes | E19: Interno | F19: True
B20: Projeto | C20: 4 | D20: Ser adaptável às variações de louça | E20: Interno | F20: True
B21: Fabricação | C21: 5 | D21: Ter matéria-prima acessível no mercado local | E21: Interno | F21: True
B22: Fabricação | C22: 6 | D22: Ter geometria simples de fabricar | E22: Interno | F22: True
B23: Fabricação | C23: 7 | D23: Ter geometria repetível entre lotes | E23: Interno | F23: True
B24: Armazenagem de peças | C24: 8 | D24: Ter peças identificáveis visualmente | E24: Interno | F24: True
B25: Armazenagem de peças | C25: 9 | D25: Resistir à degradação por umidade no estoque | E25: Interno | F25: True
B26: Armazenagem de peças | C26: 10 | D26: Ter peças empilháveis | E26: Interno | F26: True
B27: Montagem | C27: 11 | D27: Ter encaixes intuitivos | E27: Interno | F27: True
B28: Montagem | C28: 12 | D28: Ter montagem em poucas etapas | E28: Interno | F28: True
... B60: Descarte | C60: 44 | D60: Ter materiais recicláveis | E60: Externo | F60: True

Sheet Rastreabilidade
A1: ID | B1: Etapa do ciclo de vida | C1: Necessidade (característica do produto) | D1: Atributo | E1: Letra | F1: Requisito do cliente | G1: Aspecto
A2: N-28 | B2: Função | C2: Amortecer impactos do transporte | D2: Funcionamento | E2: A | F2: Amortecer impactos do transporte | G2: Desempenho funcional
A3: N-29 | B3: Função | C3: Imobilizar a louça | D3: Funcionamento | E3: B | F3: Imobilizar a louça | G3: Desempenho funcional
A4: N-30 | B4: Função | C4: Evitar atrito entre a louça e o produto | D4: Funcionamento | E4: B | F4: Imobilizar a louça | G4: Desempenho funcional
A5: N-31 | B5: Função | C5: Permitir conferir a integridade da louça sem abrir | D5: Funcionamento | E5: C | F5: Permitir conferência sem abrir | G5: Desempenho funcional
A6: N-04 | B6: Projeto | C6: Ser adaptável às variações de louça | D6: Funcionamento | E6: D | F6: Ser ajustável a diferentes louças | G6: Desempenho funcional
A7: N-26 | B7: Uso no distribuidor | C7: Acomodar as variações de louça do distribuidor | D7: Funcionamento | E7: D | F7: Ser ajustável a diferentes louças | G7: Desempenho funcional
A8: N-21 | B8: Distribuição | C8: Ser compatível com o arranjo de carga do veículo | D8: Funcionamento | E8: E | F8: Ser compatível com o veículo | G8: Desempenho funcional
A9: N-32 | B9: Movimentação na obra | C9: Ter dimensões compatíveis com as passagens da obra | D9: Ergonomia e segurança | E9: F | F9: Ser de fácil movimentação | G9: Fatores humanos
A10: N-33 | B10: Movimentação na obra | C10: Ter peso compatível com o transporte por duas pessoas | D10: Ergonomia e segurança | E10: F | F10: Ser de fácil movimentação | G10: Fatores humanos
A11: N-25 | B11: Uso no distribuidor | C11: Ter pontos de pega definidos | D11: Ergonomia e segurança | E11: G | F11: Ter pontos de pega definidos | G11: Fatores humanos
A12: N-34 | B12: Movimentação na obra | C12: Permitir retirar a louça sem contato com aresta cortante | D12: Ergonomia e segurança | E12: H | F12: Ter retirada segura da louça | G12: Fatores humanos
... A45: N-37 | B45: Manutenção | C45: Ter peça de reposição de baixo custo | D45: Econômico | E45: V | F45: Ter baixo custo por ciclo de uso | G45: Recursos e manufatura
A47: 44 necessidades geraram 22 requisitos em 44 ligações. Verificado nos dois sentidos: todo requisito tem necessidade de origem e toda necessidade aparece em algum requisito. O agrupamento é o que a matriz de atributos realiza: necessidades de fases diferentes que caem no mesmo atributo viram um requisito só.

Sheet Diagrama de Kano
B1: ID | C1: Requisito do Cliente | D1: Classe de Kano
B2: A | C2: Amortecer impactos do transporte | D2: Básico
B3: B | C3: Imobilizar a louça | D3: Básico
B4: C | C4: Permitir conferência sem abrir | D4: Atrativo
B5: D | C5: Ser ajustável a diferentes louças | D5: Desempenho
B6: E | C6: Ser compatível com o veículo | D6: Básico
B7: F | C7: Ser de fácil movimentação | D7: Desempenho
B8: G | C8: Ter pontos de pega definidos | D8: Básico
B9: H | C9: Ter retirada segura da louça | D9: Básico
B10: I | C10: Ser de uso intuitivo | D10: Desempenho
B11: J | C11: Ser compacto | D11: Desempenho
B12: K | C12: Ser empilhável | D12: Básico
... B23: V | C23: Ter baixo custo por ciclo de uso | D23: Desempenho
B24: W | C24: Ser estável quando apoiado | D24: Básico | F24: Classificação: Atrativo; Desempenho e Básico
B27: Classificação preliminar da equipe, informada pelo levantamento qualitativo. Não houve questionário funcional/disfuncional Kano nesta rodada. Confirmar ou revisar com clientes ao ampliar o campo. | C27: Classificação preliminar da equipe, informada pelo levantamento qualitativo. Não houve questionário funcional/disfuncional Kano nesta rodada. Confirmar ou revisar com clientes ao ampliar o campo. | D27: Classificação preliminar da equipe, informada pelo levantamento qualitativo. Não houve questionário funcional/disfuncional Kano nesta rodada. Confirmar ou revisar com clientes ao ampliar o campo. | E27: Classificação preliminar da equipe, informada pelo levantamento qualitativo. Não houve questionário funcional/disfuncional Kano nesta rodada. Confirmar ou revisar com clientes ao ampliar o campo. | F27: Classificação preliminar da equipe, informada pelo levantamento qualitativo. Não houve questionário funcional/disfuncional Kano nesta rodada. Confirmar ou revisar com clientes ao ampliar o campo.
B29: Kano descreve a resposta de satisfação; não determina quem vence o Mudge. C (atrativo) tem 45 pontos, N (básico) tem 2 e S (atrativo) tem 0. Baixo peso não exclui requisito ou meta. | C29: Kano descreve a resposta de satisfação; não determina quem vence o Mudge. C (atrativo) tem 45 pontos, N (básico) tem 2 e S (atrativo) tem 0. Baixo peso não exclui requisito ou meta. | D29: Kano descreve a resposta de satisfação; não determina quem vence o Mudge. C (atrativo) tem 45 pontos, N (básico) tem 2 e S (atrativo) tem 0. Baixo peso não exclui requisito ou meta. | E29: Kano descreve a resposta de satisfação; não determina quem vence o Mudge. C (atrativo) tem 45 pontos, N (básico) tem 2 e S (atrativo) tem 0. Baixo peso não exclui requisito ou meta. | F29: Kano descreve a resposta de satisfação; não determina quem vence o Mudge. C (atrativo) tem 45 pontos, N (básico) tem 2 e S (atrativo) tem 0. Baixo peso não exclui requisito ou meta.

Sheet Diagrama de Mudge
G2: Qual requisito é mais importante para o sucesso do produto? Quanto mais importante é este requisito?
B5: REQUISITO DO CLIENTE | C5: ID | G5: A | H5: B | I5: C | J5: D | K5: E | L5: F | M5: G | N5: H | O5: I | P5: J | Q5: K | R5: L | S5: M | T5: N | U5: O | V5: P | W5: Q | X5: R | Y5: S | Z5: T | AA5: U | AB5: V | AC5: W | AD5: Somatório da letra
B6: Amortecer impactos do transporte | C6: A | D6: Básico | F6: A | G6: X | H6: A1 | I6: A5 | J6: A3 | K6: A3 | L6: A3 | M6: A5 | N6: A1 | O6: A3 | P6: A3 | Q6: A3 | R6: A3 | S6: A3 | T6: A5 | U6: A3 | V6: A3 | W6: A5 | X6: A5 | Y6: A5 | Z6: A5 | AA6: A5 | AB6: A3 | AC6: A3 | AD6: =COUNTIF($G$6:$AC$28,F6&"1")+COUNTIF($G$6:$AC$28,F6&"3")*3+COUNTIF($G$6:$AC$28,F6&"5")*5
B7: Imobilizar a louça | C7: B | D7: Básico | F7: B | H7: X | I7: B3 | J7: B3 | K7: B3 | L7: B1 | M7: B3 | N7: B1 | O7: B3 | P7: B3 | Q7: B5 | R7: B3 | S7: B5 | T7: B5 | U7: B3 | V7: B5 | W7: B5 | X7: B5 | Y7: B5 | Z7: B5 | AA7: B5 | AB7: B3 | AC7: B3 | AD7: =COUNTIF($G$6:$AC$28,F7&"1")+COUNTIF($G$6:$AC$28,F7&"3")*3+COUNTIF($G$6:$AC$28,F7&"5")*5
B8: Permitir conferência sem abrir | C8: C | D8: Atrativo | F8: C | I8: X | J8: C1 | K8: C1 | L8: F1 | M8: C1 | N8: C1 | O8: C1 | P8: C3 | Q8: C3 | R8: C3 | S8: C1 | T8: C3 | U8: C3 | V8: C3 | W8: C3 | X8: C5 | Y8: C5 | Z8: C3 | AA8: C3 | AB8: C1 | AC8: C1 | AD8: =COUNTIF($G$6:$AC$28,F8&"1")+COUNTIF($G$6:$AC$28,F8&"3")*3+COUNTIF($G$6:$AC$28,F8&"5")*5
B9: Ser ajustável a diferentes louças | C9: D | D9: Desempenho | F9: D | J9: X | K9: D1 | L9: F3 | M9: D1 | N9: H1 | O9: D1 | P9: D1 | Q9: D1 | R9: D1 | S9: D3 | T9: D3 | U9: D1 | V9: D3 | W9: D3 | X9: D5 | Y9: D5 | Z9: D1 | AA9: D3 | AB9: D1 | AC9: D1 | AD9: =COUNTIF($G$6:$AC$28,F9&"1")+COUNTIF($G$6:$AC$28,F9&"3")*3+COUNTIF($G$6:$AC$28,F9&"5")*5
B10: Ser compatível com o veículo | C10: E | D10: Básico | F10: E | K10: X | L10: F3 | M10: G1 | N10: H1 | O10: E1 | P10: E1 | Q10: E1 | R10: E1 | S10: E1 | T10: E3 | U10: E1 | V10: E1 | W10: E3 | X10: E3 | Y10: E3 | Z10: E3 | AA10: E3 | AB10: E1 | AC10: E1 | AD10: =COUNTIF($G$6:$AC$28,F10&"1")+COUNTIF($G$6:$AC$28,F10&"3")*3+COUNTIF($G$6:$AC$28,F10&"5")*5
B11: Ser de fácil movimentação | C11: F | D11: Desempenho | F11: F | L11: X | M11: F1 | N11: F1 | O11: F3 | P11: F3 | Q11: F3 | R11: F3 | S11: F5 | T11: F5 | U11: F3 | V11: F5 | W11: F5 | X11: F5 | Y11: F5 | Z11: F5 | AA11: F5 | AB11: F3 | AC11: F3 | AD11: =COUNTIF($G$6:$AC$28,F11&"1")+COUNTIF($G$6:$AC$28,F11&"3")*3+COUNTIF($G$6:$AC$28,F11&"5")*5
B12: Ter pontos de pega definidos | C12: G | D12: Básico | F12: G | M12: X | N12: G1 | O12: G1 | P12: G1 | Q12: G1 | R12: G1 | S12: G3 | T12: G3 | U12: G1 | V12: G3 | W12: G3 | X12: G5 | Y12: G5 | Z12: G3 | AA12: G3 | AB12: G1 | AC12: G1 | AD12: =COUNTIF($G$6:$AC$28,F12&"1")+COUNTIF($G$6:$AC$28,F12&"3")*3+COUNTIF($G$6:$AC$28,F12&"5")*5
B13: Ter retirada segura da louça | C13: H | D13: Básico | F13: H | N13: X | O13: H1 | P13: H1 | Q13: H3 | R13: H1 | S13: H1 | T13: H3 | U13: H1 | V13: H3 | W13: H3 | X13: H5 | Y13: H5 | Z13: H3 | AA13: H3 | AB13: H1 | AC13: H1 | AD13: =COUNTIF($G$6:$AC$28,F13&"1")+COUNTIF($G$6:$AC$28,F13&"3")*3+COUNTIF($G$6:$AC$28,F13&"5")*5
B14: Ser de uso intuitivo | C14: I | D14: Desempenho | F14: I | O14: X | P14: I1 | Q14: I1 | R14: I1 | S14: I1 | T14: I3 | U14: I1 | V14: I1 | W14: I3 | X14: I3 | Y14: I3 | Z14: I3 | AA14: I1 | AB14: V1 | AC14: W1 | AD14: =COUNTIF($G$6:$AC$28,F14&"1")+COUNTIF($G$6:$AC$28,F14&"3")*3+COUNTIF($G$6:$AC$28,F14&"5")*5
B15: Ser compacto | C15: J | D15: Desempenho | F15: J | P15: X | Q15: K1 | R15: L1 | S15: J1 | T15: J3 | U15: O1 | V15: J1 | W15: J1 | X15: J3 | Y15: J3 | Z15: J1 | AA15: J1 | AB15: V1 | AC15: W1 | AD15: =COUNTIF($G$6:$AC$28,F15&"1")+COUNTIF($G$6:$AC$28,F15&"3")*3+COUNTIF($G$6:$AC$28,F15&"5")*5
B16: Ser empilhável | C16: K | D16: Básico | F16: K | Q16: X | R16: K1 | S16: K1 | T16: K3 | U16: K1 | V16: K1 | W16: K1 | X16: K3 | Y16: K3 | Z16: K1 | AA16: K1 | AB16: V1 | AC16: W1 | AD16: =COUNTIF($G$6:$AC$28,F16&"1")+COUNTIF($G$6:$AC$28,F16&"3")*3+COUNTIF($G$6:$AC$28,F16&"5")*5
B17: Ter desempenho uniforme | C17: L | D17: Básico | F17: L | R17: X | S17: L1 | T17: L3 | U17: L1 | V17: L1 | W17: L1 | X17: L3 | Y17: L3 | Z17: L1 | AA17: L1 | AB17: V1 | AC17: W1 | AD17: =COUNTIF($G$6:$AC$28,F17&"1")+COUNTIF($G$6:$AC$28,F17&"3")*3+COUNTIF($G$6:$AC$28,F17&"5")*5
B18: Ter indicação visual de uso | C18: M | D18: Atrativo | F18: M | S18: X | T18: M1 | U18: O1 | V18: P1 | W18: M1 | X18: M3 | Y18: M3 | Z18: M1 | AA18: M1 | AB18: V1 | AC18: W1 | AD18: =COUNTIF($G$6:$AC$28,F18&"1")+COUNTIF($G$6:$AC$28,F18&"3")*3+COUNTIF($G$6:$AC$28,F18&"5")*5
B19: Ter identificação visível | C19: N | D19: Básico | F19: N | T19: X | U19: O3 | V19: P1 | W19: Q1 | X19: N1 | Y19: N1 | Z19: T1 | AA19: U1 | AB19: V3 | AC19: W3 | AD19: =COUNTIF($G$6:$AC$28,F19&"1")+COUNTIF($G$6:$AC$28,F19&"3")*3+COUNTIF($G$6:$AC$28,F19&"5")*5
B20: Ser reutilizável | C20: O | D20: Desempenho | F20: O | U20: X | V20: O1 | W20: O1 | X20: O3 | Y20: O3 | Z20: O1 | AA20: O1 | AB20: V1 | AC20: W1 | AD20: =COUNTIF($G$6:$AC$28,F20&"1")+COUNTIF($G$6:$AC$28,F20&"3")*3+COUNTIF($G$6:$AC$28,F20&"5")*5
B21: Ser resistente a intempéries | C21: P | D21: Básico | F21: P | V21: X | W21: P1 | X21: P3 | Y21: P3 | Z21: P1 | AA21: P1 | AB21: V1 | AC21: W1 | AD21: =COUNTIF($G$6:$AC$28,F21&"1")+COUNTIF($G$6:$AC$28,F21&"3")*3+COUNTIF($G$6:$AC$28,F21&"5")*5
B22: Ter manutenção simples | C22: Q | D22: Desempenho | F22: Q | W22: X | X22: Q1 | Y22: Q1 | Z22: T1 | AA22: U1 | AB22: V3 | AC22: W3 | AD22: =COUNTIF($G$6:$AC$28,F22&"1")+COUNTIF($G$6:$AC$28,F22&"3")*3+COUNTIF($G$6:$AC$28,F22&"5")*5
B23: Ser de fácil desmontagem | C23: R | D23: Desempenho | F23: R | X23: X | Y23: R1 | Z23: T1 | AA23: U1 | AB23: V3 | AC23: W3 | AD23: =COUNTIF($G$6:$AC$28,F23&"1")+COUNTIF($G$6:$AC$28,F23&"3")*3+COUNTIF($G$6:$AC$28,F23&"5")*5
B24: Ter materiais recicláveis | C24: S | D24: Atrativo | F24: S | Y24: X | Z24: T1 | AA24: U1 | AB24: V3 | AC24: W3 | AD24: =COUNTIF($G$6:$AC$28,F24&"1")+COUNTIF($G$6:$AC$28,F24&"3")*3+COUNTIF($G$6:$AC$28,F24&"5")*5
B25: Ter peças modulares | C25: T | D25: Desempenho | F25: T | Z25: X | AA25: T1 | AB25: V3 | AC25: W3 | AD25: =COUNTIF($G$6:$AC$28,F25&"1")+COUNTIF($G$6:$AC$28,F25&"3")*3+COUNTIF($G$6:$AC$28,F25&"5")*5
B26: Ter montagem em poucas etapas | C26: U | D26: Desempenho | F26: U | AA26: X | AB26: V3 | AC26: W3 | AD26: =COUNTIF($G$6:$AC$28,F26&"1")+COUNTIF($G$6:$AC$28,F26&"3")*3+COUNTIF($G$6:$AC$28,F26&"5")*5
B27: Ter baixo custo por ciclo de uso | C27: V | D27: Desempenho | F27: V | AB27: X | AC27: W1 | AD27: =COUNTIF($G$6:$AC$28,F27&"1")+COUNTIF($G$6:$AC$28,F27&"3")*3+COUNTIF($G$6:$AC$28,F27&"5")*5
B28: Ser estável quando apoiado | C28: W | D28: Básico | F28: W | AC28: X | AD28: =COUNTIF($G$6:$AC$28,F28&"1")+COUNTIF($G$6:$AC$28,F28&"3")*3+COUNTIF($G$6:$AC$28,F28&"5")*5
AB29: Total | AC29: Total | AD29: =SUM(AD6:AD28)
B31: Um requisito é considerado muito mais importante do que o outro (VALOR 5)
B32: Um requisito é considerado mais importante do que o outro (VALOR 3)
B33: Um requisito é considerado pouco mais importante do que o outro (VALOR 1)
B34: Os requisitos são considerados de igual importância (VALOR 0)
B36: Base da comparação: cada par foi julgado pela pergunta da Aula 12 — qual requisito é mais importante para o sucesso do produto e quanto mais importante. As notas C1, C2 e C3 abaixo servem de âncora comum para que a comparação não fique arbitrária; em 17 dos 253 pares o julgamento do par se afastou dessa âncora, e cada um deles está registrado na tabela de desvios com a razão. Primeiro passe da equipe, a revalidar com o distribuidor.
B38: C1 · Avaria | C38: Reduz diretamente a quebra no trecho distribuidor–obra
B39: C2 · Trabalhador | C39: Reduz esforço, queda e exposição a corte
B40: C3 · Adoção | C40: Determina o distribuidor comprar e usar: custo, ritmo e compatibilidade
B42: Requisito do cliente | C42: ID | D42: C1 | E42: C2 | F42: C3 | G42: Soma
B43: Amortecer impactos do transporte | C43: A | D43: 5 | E43: 2 | F43: 3 | G43: =SUM(D43:F43)
B44: Imobilizar a louça | C44: B | D44: 5 | E44: 3 | F44: 3 | G44: =SUM(D44:F44)
B45: Permitir conferência sem abrir | C45: C | D45: 1 | E45: 4 | F45: 4 | G45: =SUM(D45:F45)
B46: Ser ajustável a diferentes louças | C46: D | D46: 3 | E46: 1 | F46: 4 | G46: =SUM(D46:F46)
B47: Ser compatível com o veículo | C47: E | D47: 3 | E47: 1 | F47: 3 | G47: =SUM(D47:F47)
...

Sheet Diagrama de Pareto
A1: Requisito | B1: ID | C1: Pontuação | D1: Frequência | E1: Frequência Acumulada | F1: Grau de Importância | G1: Classe de Pareto
A2: Amortecer impactos do transporte | B2: A | C2: ='Diagrama de Mudge'!AD6 | D2: =C2/$C$25 | E2: =D2 | F2: =IF(C2=0,0,MAX(1,ROUND(C2/MAX($C$2:$C$24)*5,0))) | G2: ="A · vital"
A3: Imobilizar a louça | B3: B | C3: ='Diagrama de Mudge'!AD7 | D3: =C3/$C$25 | E3: =D3+E2 | F3: =IF(C3=0,0,MAX(1,ROUND(C3/MAX($C$2:$C$24)*5,0))) | G3: =IF(E2<0.8,"A · vital","B · trivial")
A4: Ser de fácil movimentação | B4: F | C4: ='Diagrama de Mudge'!AD11 | D4: =C4/$C$25 | E4: =D4+E3 | F4: =IF(C4=0,0,MAX(1,ROUND(C4/MAX($C$2:$C$24)*5,0))) | G4: =IF(E3<0.8,"A · vital","B · trivial")
A5: Permitir conferência sem abrir | B5: C | C5: ='Diagrama de Mudge'!AD8 | D5: =C5/$C$25 | E5: =D5+E4 | F5: =IF(C5=0,0,MAX(1,ROUND(C5/MAX($C$2:$C$24)*5,0))) | G5: =IF(E4<0.8,"A · vital","B · trivial")
A6: Ter pontos de pega definidos | B6: G | C6: ='Diagrama de Mudge'!AD12 | D6: =C6/$C$25 | E6: =D6+E5 | F6: =IF(C6=0,0,MAX(1,ROUND(C6/MAX($C$2:$C$24)*5,0))) | G6: =IF(E5<0.8,"A · vital","B · trivial")
A7: Ter retirada segura da louça | B7: H | C7: ='Diagrama de Mudge'!AD13 | D7: =C7/$C$25 | E7: =D7+E6 | F7: =IF(C7=0,0,MAX(1,ROUND(C7/MAX($C$2:$C$24)*5,0))) | G7: =IF(E6<0.8,"A · vital","B · trivial")
A8: Ser ajustável a diferentes louças | B8: D | C8: ='Diagrama de Mudge'!AD9 | D8: =C8/$C$25 | E8: =D8+E7 | F8: =IF(C8=0,0,MAX(1,ROUND(C8/MAX($C$2:$C$24)*5,0))) | G8: =IF(E7<0.8,"A · vital","B · trivial")
A9: Ser compatível com o veículo | B9: E | C9: ='Diagrama de Mudge'!AD10 | D9: =C9/$C$25 | E9: =D9+E8 | F9: =IF(C9=0,0,MAX(1,ROUND(C9/MAX($C$2:$C$24)*5,0))) | G9: =IF(E8<0.8,"A · vital","B · trivial")
A10: Ser estável quando apoiado | B10: W | C10: ='Diagrama de Mudge'!AD28 | D10: =C10/$C$25 | E10: =D10+E9 | F10: =IF(C10=0,0,MAX(1,ROUND(C10/MAX($C$2:$C$24)*5,0))) | G10: =IF(E9<0.8,"A · vital","B · trivial")
A11: Ter baixo custo por ciclo de uso | B11: V | C11: ='Diagrama de Mudge'!AD27 | D11: =C11/$C$25 | E11: =D11+E10 | F11: =IF(C11=0,0,MAX(1,ROUND(C11/MAX($C$2:$C$24)*5,0))) | G11: =IF(E10<0.8,"A · vital","B · trivial")
A12: Ser de uso intuitivo | B12: I | C12: ='Diagrama de Mudge'!AD14 | D12: =C12/$C$25 | E12: =D12+E11 | F12: =IF(C12=0,0,MAX(1,ROUND(C12/MAX($C$2:$C$24)*5,0))) | G12: =IF(E11<0.8,"A · vital","B · trivial")
A13: Ser empilhável | B13: K | C13: ='Diagrama de Mudge'!AD16 | D13: =C13/$C$25 | E13: =D13+E12 | F13: =IF(C13=0,0,MAX(1,ROUND(C13/MAX($C$2:$C$24)*5,0))) | G13: =IF(E12<0.8,"A · vital","B · trivial")
A14: Ter desempenho uniforme | B14: L | C14: ='Diagrama de Mudge'!AD17 | D14: =C14/$C$25 | E14: =D14+E13 | F14: =IF(C14=0,0,MAX(1,ROUND(C14/MAX($C$2:$C$24)*5,0))) | G14: =IF(E13<0.8,"A · vital","B · trivial")
A15: Ser reutilizável | B15: O | C15: ='Diagrama de Mudge'!AD20 | D15: =C15/$C$25 | E15: =D15+E14 | F15: =IF(C15=0,0,MAX(1,ROUND(C15/MAX($C$2:$C$24)*5,0))) | G15: =IF(E14<0.8,"A · vital","B · trivial")
A16: Ser compacto | B16: J | C16: ='Diagrama de Mudge'!AD15 | D16: =C16/$C$25 | E16: =D16+E15 | F16: =IF(C16=0,0,MAX(1,ROUND(C16/MAX($C$2:$C$24)*5,0))) | G16: =IF(E15<0.8,"A · vital","B · trivial")
A17: Ser resistente a intempéries | B17: P | C17: ='Diagrama de Mudge'!AD21 | D17: =C17/$C$25 | E17: =D17+E16 | F17: =IF(C17=0,0,MAX(1,ROUND(C17/MAX($C$2:$C$24)*5,0))) | G17: =IF(E16<0.8,"A · vital","B · trivial")
A18: Ter indicação visual de uso | B18: M | C18: ='Diagrama de Mudge'!AD18 | D18: =C18/$C$25 | E18: =D18+E17 | F18: =IF(C18=0,0,MAX(1,ROUND(C18/MAX($C$2:$C$24)*5,0))) | G18: =IF(E17<0.8,"A · vital","B · trivial")
A19: Ter peças modulares | B19: T | C19: ='Diagrama de Mudge'!AD25 | D19: =C19/$C$25 | E19: =D19+E18 | F19: =IF(C19=0,0,MAX(1,ROUND(C19/MAX($C$2:$C$24)*5,0))) | G19: =IF(E18<0.8,"A · vital","B · trivial")
A20: Ter montagem em poucas etapas | B20: U | C20: ='Diagrama de Mudge'!AD26 | D20: =C20/$C$25 | E20: =D20+E19 | F20: =IF(C20=0,0,MAX(1,ROUND(C20/MAX($C$2:$C$24)*5,0))) | G20: =IF(E19<0.8,"A · vital","B · trivial")
A21: Ter manutenção simples | B21: Q | C21: ='Diagrama de Mudge'!AD22 | D21: =C21/$C$25 | E21: =D21+E20 | F21: =IF(C21=0,0,MAX(1,ROUND(C21/MAX($C$2:$C$24)*5,0))) | G21: =IF(E20<0.8,"A · vital","B · trivial")
A22: Ter identificação visível | B22: N | C22: ='Diagrama de Mudge'!AD19 | D22: =C22/$C$25 | E22: =D22+E21 | F22: =IF(C22=0,0,MAX(1,ROUND(C22/MAX($C$2:$C$24)*5,0))) | G22: =IF(E21<0.8,"A · vital","B · trivial")
A23: Ser de fácil desmontagem | B23: R | C23: ='Diagrama de Mudge'!AD23 | D23: =C23/$C$25 | E23: =D23+E22 | F23: =IF(C23=0,0,MAX(1,ROUND(C23/MAX($C$2:$C$24)*5,0))) | G23: =IF(E22<0.8,"A · vital","B · trivial")
A24: Ter materiais recicláveis | B24: S | C24: ='Diagrama de Mudge'!AD24 | D24: =C24/$C$25 | E24: =D24+E23 | F24: =IF(C24=0,0,MAX(1,ROUND(C24/MAX($C$2:$C$24)*5,0))) | G24: =IF(E23<0.8,"A · vital","B · trivial")
C25: =SUM(C2:C24) | D25: =SUM(D2:D24)
A28: O grau de importância 0–5 resume a pontuação do Mudge e é usado na triagem Pugh. A quantificação técnica do QFD usa a pontuação bruta de Mudge, conforme a Matriz de Relacionamento.
A30: Kano e Mudge são complementares: a classe de satisfação não determina vitória nos pares. C é atrativo e tem alta importância; N é básico e tem baixo peso. Classe B ou peso zero não elimina requisitos e metas. | B30: Kano e Mudge são complementares: a classe de satisfação não determina vitória nos pares. C é atrativo e tem alta importância; N é básico e tem baixo peso. Classe B ou peso zero não elimina requisitos e metas. | C30: Kano e Mudge são complementares: a classe de satisfação não determina vitória nos pares. C é atrativo e tem alta importância; N é básico e tem baixo peso. Classe B ou peso zero não elimina requisitos e metas. | D30: Kano e Mudge são complementares: a classe de satisfação não determina vitória nos pares. C é atrativo e tem alta importância; N é básico e tem baixo peso. Classe B ou peso zero não elimina requisitos e metas. | E30: Kano e Mudge são complementares: a classe de satisfação não determina vitória nos pares. C é atrativo e tem alta importância; N é básico e tem baixo peso. Classe B ou peso zero não elimina requisitos e metas. | F30: Kano e Mudge são complementares: a classe de satisfação não determina vitória nos pares. C é atrativo e tem alta importância; N é básico e tem baixo peso. Classe B ou peso zero não elimina requisitos e metas. | G30: Kano e Mudge são complementares: a classe de satisfação não determina vitória nos pares. C é atrativo e tem alta importância; N é básico e tem baixo peso. Classe B ou peso zero não elimina requisitos e metas.
A33: Kano–Mudge — interpretação dos resultados no recorte investigado | B33: Kano–Mudge — interpretação dos resultados no recorte investigado | C33: Kano–Mudge — interpretação dos resultados no recorte investigado | D33: Kano–Mudge — interpretação dos resultados no recorte investigado | E33: Kano–Mudge — interpretação dos resultados no recorte investigado | F33: Kano–Mudge — interpretação dos resultados no recorte investigado | G33: Kano–Mudge — interpretação dos resultados no recorte investigado
A34: Requisito | B34: ID | C34: Kano | D34: Pontos Mudge | E34: Posição no Pareto | F34: Diretriz | G34: RP relacionados
A35: =INDEX($A$2:$A$24,MATCH(B35,$B$2:$B$24,0)) -> Amortecer impactos do transporte | B35: A | C35: =INDEX('Diagrama de Kano'!$D$2:$D$24,MATCH(B35,'Diagrama de Kano'!$B$2:$B$24,0)) -> Básico | D35: =INDEX($C$2:$C$24,MATCH(B35,$B$2:$B$24,0)) -> 78 | E35: =MATCH(B35,$B$2:$B$24,0) -> 1 | F35: Priorizar proteção; ensaiar aceleração | G35: RP1
A36: =INDEX($A$2:$A$24,MATCH(B36,$B$2:$B$24,0)) -> Imobilizar a louça | B36: B | C36: =INDEX('Diagrama de Kano'!$D$2:$D$24,MATCH(B36,'Diagrama de Kano'!$B$2:$B$24,0)) -> Básico | D36: =INDEX($C$2:$C$24,MATCH(B36,$B$2:$B$24,0)) -> 77 | E36: =MATCH(B36,$B$2:$B$24,0) -> 2 | F36: Priorizar imobilização; medir deslocamento | G36: RP2
A37: =INDEX($A$2:$A$24,MATCH(B37,$B$2:$B$24,0)) -> Ser de fácil movimentação | B37: F | C37: =INDEX('Diagrama de Kano'!$D$2:$D$24,MATCH(B37,'Diagrama de Kano'!$B$2:$B$24,0)) -> Desempenho | D37: =INDEX($C$2:$C$24,MATCH(B37,$B$2:$B$24,0)) -> 70 | E37: =MATCH(B37,$B$2:$B$24,0) -> 3 | F37: Confrontar proteção com esforço e acesso | G37: RP3, RP5
A38: =INDEX($A$2:$A$24,MATCH(B38,$B$2:$B$24,0)) -> Permitir conferência sem abrir | B38: C | C38: =INDEX('Diagrama de Kano'!$D$2:$D$24,MATCH(B38,'Diagrama de Kano'!$B$2:$B$24,0)) -> Atrativo | D38: =INDEX($C$2:$C$24,MATCH(B38,$B$2:$B$24,0)) -> 45 | E38: =MATCH(B38,$B$2:$B$24,0) -> 4 | F38: Atrativo de alta importância; comprovar inspeção da cerâmica | G38: RP4
A39: =INDEX($A$2:$A$24,MATCH(B39,$B$2:$B$24,0)) -> Ser empilhável | B39: K | C39: =INDEX('Diagrama de Kano'!$D$2:$D$24,MATCH(B39,'Diagrama de Kano'!$B$2:$B$24,0)) -> Básico | D39: =INDEX($C$2:$C$24,MATCH(B39,$B$2:$B$24,0)) -> 17 | E39: =MATCH(B39,$B$2:$B$24,0) -> 12 | F39: Fora dos onze vitais; empilhamento continua exigido | G39: RP11
A40: =INDEX($A$2:$A$24,MATCH(B40,$B$2:$B$24,0)) -> Ter identificação visível | B40: N | C40: =INDEX('Diagrama de Kano'!$D$2:$D$24,MATCH(B40,'Diagrama de Kano'!$B$2:$B$24,0)) -> Básico | D40: =INDEX($C$2:$C$24,MATCH(B40,$B$2:$B$24,0)) -> 2 | E40: =MATCH(B40,$B$2:$B$24,0) -> 21 | F40: Peso baixo; identificação e orientação permanecem | G40: RP16, RP21
A41: =INDEX($A$2:$A$24,MATCH(B41,$B$2:$B$24,0)) -> Ter materiais recicláveis | B41: S | C41: =INDEX('Diagrama de Kano'!$D$2:$D$24,MATCH(B41,'Diagrama de Kano'!$B$2:$B$24,0)) -> Atrativo | D41: =INDEX($C$2:$C$24,MATCH(B41,$B$2:$B$24,0)) -> 0 | E41: =MATCH(B41,$B$2:$B$24,0) -> 23 | F41: Peso zero; meta de fim de vida permanece | G41: RP19
A43: A classe Kano acompanha a interpretação do QFD; a quantificação usa os pontos brutos do Mudge, sem multiplicador de classe. Rever categorias e pares se as novas entrevistas mudarem a interpretação; atualizar Pareto, QFD e seleção na mesma rodada. | B43: A classe Kano acompanha a interpretação do QFD; a quantificação usa os pontos brutos do Mudge, sem multiplicador de classe. Rever categorias e pares se as novas entrevistas mudarem a interpretação; atualizar Pareto, QFD e seleção na mesma rodada. | C43: A classe Kano acompanha a interpretação do QFD; a quantificação usa os pontos brutos do Mudge, sem multiplicador de classe. Rever categorias e pares se as novas entrevistas mudarem a interpretação; atualizar Pareto, QFD e seleção na mesma rodada. | D43: A classe Kano acompanha a interpretação do QFD; a quantificação usa os pontos brutos do Mudge, sem multiplicador de classe. Rever categorias e pares se as novas entrevistas mudarem a interpretação; atualizar Pareto, QFD e seleção na mesma rodada. | E43: A classe Kano acompanha a interpretação do QFD; a quantificação usa os pontos brutos do Mudge, sem multiplicador de classe. Rever categorias e pares se as novas entrevistas mudarem a interpretação; atualizar Pareto, QFD e seleção na mesma rodada. | F43: A classe Kano acompanha a interpretação do QFD; a quantificação usa os pontos brutos do Mudge, sem multiplicador de classe. Rever categorias e pares se as novas entrevistas mudarem a interpretação; atualizar Pareto, QFD e seleção na mesma rodada. | G43: A classe Kano acompanha a interpretação do QFD; a quantificação usa os pontos brutos do Mudge, sem multiplicador de classe. Rever categorias e pares se as novas entrevistas mudarem a interpretação; atualizar Pareto, QFD e seleção na mesma rodada.

Sheet Benchmarking
B2: Benchmarking
B4: R1 | C4: Embalagem de papelão do fabricante | D4: Caixa de papelão com berço interno, uma viagem. Padrão observado no estoque do distribuidor e no recebimento da obra (Semana 03).
B5: R2 | C5: Engradado de madeira com calços | D5: Caixa de ripas com calços internos, usada em cargas especiais e longas distâncias. Referência de mercado descrita pelo distribuidor.
B6: R3 | C6: Palete com filme stretch e cantoneiras | D6: Unitização da expedição: caixas sobre palete, filme stretch e cantoneiras de papelão. Observado na expedição do distribuidor.
B7: R4 | C7: Sistema de encaixes de papelão — US9221577B2 | D7: Estado da arte documental. Encaixes de papelão que posicionam bacia, caixa acoplada e tampa; a especificação reivindica cerca de 27% menos volume de embalagem. Avaliado por especificação, não por observação.
B9: ID | C9: Requisito do cliente | D9: Kano | E9: Pontuação Mudge | F9: R1 Embalagem de papelão do fabricante | G9: R2 Engradado de madeira com calços | H9: R3 Palete com filme stretch e cantoneiras | I9: R4 Sistema de encaixes de papelão — US9221577B2 | J9: Melhor | K9: Base da avaliação
B10: ='Diagrama de Pareto'!B2 | C10: ='Diagrama de Pareto'!A2 | D10: {=INDEX('Diagrama de Kano'!$D$2:$D$24,MATCH($B10,'Diagrama de Kano'!$B$2:$B$24,0))} | E10: ='Diagrama de Pareto'!C2 | F10: 3 | G10: 4 | H10: 3 | I10: 5 | J10: =MAX(F10:I10) | K10: O filme prende a caixa ao palete, não a peça dentro dela. Os encaixes da patente restringem as três peças e reduzem contato entre elas.
B11: ='Diagrama de Pareto'!B3 | C11: ='Diagrama de Pareto'!A3 | D11: {=INDEX('Diagrama de Kano'!$D$2:$D$24,MATCH($B11,'Diagrama de Kano'!$B$2:$B$24,0))} | E11: ='Diagrama de Pareto'!C3 | F11: 3 | G11: 2 | H11: 3 | I11: 3 | J11: =MAX(F11:I11) | K11: Campo: quando o carrinho não acessa o ponto, a movimentação vira manual. O palete resolve o pátio e não o último trecho.
B12: ='Diagrama de Pareto'!B4 | C12: ='Diagrama de Pareto'!A4 | D12: {=INDEX('Diagrama de Kano'!$D$2:$D$24,MATCH($B12,'Diagrama de Kano'!$B$2:$B$24,0))} | E12: ='Diagrama de Pareto'!C4 | F12: 3 | G12: 4 | H12: 2 | I12: 4 | J12: =MAX(F12:I12) | K12: Campo: avarias associadas ao trecho distribuidor→obra mesmo com berço de papelão. Madeira e encaixes dedicados protegem mais; o palete apenas unitiza.
B13: ='Diagrama de Pareto'!B5 | C13: ='Diagrama de Pareto'!A5 | D13: {=INDEX('Diagrama de Kano'!$D$2:$D$24,MATCH($B13,'Diagrama de Kano'!$B$2:$B$24,0))} | E13: ='Diagrama de Pareto'!C5 | F13: 1 | G13: 2 | H13: 1 | I13: 1 | J13: =MAX(F13:I13) | K13: Nenhuma referência permite conferir a peça fechada. As frestas do engradado dão visão parcial da superfície, não de trinca.
B14: ='Diagrama de Pareto'!B6 | C14: ='Diagrama de Pareto'!A6 | D14: {=INDEX('Diagrama de Kano'!$D$2:$D$24,MATCH($B14,'Diagrama de Kano'!$B$2:$B$24,0))} | E14: ='Diagrama de Pareto'!C6 | F14: 2 | G14: 3 | H14: 1 | I14: 2 | J14: =MAX(F14:I14) | K14: Nenhuma referência define ponto de pega para a peça. As ripas servem de apoio improvisado, com risco de farpa.
B15: ='Diagrama de Pareto'!B7 | C15: ='Diagrama de Pareto'!A7 | D15: {=INDEX('Diagrama de Kano'!$D$2:$D$24,MATCH($B15,'Diagrama de Kano'!$B$2:$B$24,0))} | E15: ='Diagrama de Pareto'!C7 | F15: 2 | G15: 2 | H15: 2 | I15: 3 | J15: =MAX(F15:I15) | K15: Abertura com estilete ou saque de pregos, com o caco oculto ainda dentro. Nos encaixes a remoção é mais ordenada — inferência da especificação.
